Workbook

Sheet Balance
D1: BRIGHTEC ENERGY DYNAMICS S DE RL DE CV
A3: Balance General | D3: =B3+1 | F3: =D3+1 | H3: =F3+1&" "&"("&IF('Edo de resultados'!K2=1,"Enero",IF('Edo de resultados'!K2=2,"Febrero",IF('Edo de resultados'!K2=3,"Marzo",IF('Edo de resultados'!K2=4,"Abril",IF('Edo de resultados'!K2=5,"Mayo",IF('Edo de resultados'!K2=6,"Junio",IF('Edo de resultados'!K2=7,"Julio",IF('Edo de resultados'!K2=8,"Agosto",IF('Edo de resultados'!K2=9,"Septiembre",IF('Edo de resultados'!K2=10,"Octubre",IF('Edo de resultados'!K2=11,"Noviembre",IF('Edo de resultados'!K2=12,"Diciembre","INCORRECTO"))))))))))))&")" | K3: ="Razones"&" "&B3 | L3: ="Razones"&" "&B3+1 | M3: ="Razones"&" "&B3+2 | N3: ="Razones"&" "&B3+3
B4: Saldo | D4: Saldo | F4: Saldo | H4: Saldo
A5: Activos | K5: A) SOLVENCIA(LIQUIDEZ) Y OPERACIÓN | L5: A) SOLVENCIA(LIQUIDEZ) Y OPERACIÓN | M5: A) SOLVENCIA(LIQUIDEZ) Y OPERACIÓN | N5: A) SOLVENCIA(LIQUIDEZ) Y OPERACIÓN
A6: ACTIVO | K6: Razon circulante | L6: Razon circulante | M6: Razon circulante | N6: Razon circulante
A7: ACTIVO- CIRCULANTE | B7: Analisis vertical | D7: Analisis vertical | F7: Analisis vertical | H7: Analisis vertical | J7: HORIZ | K7: Activo circulante/pasivo circulante | L7: Activo circulante/pasivo circulante | M7: Activo circulante/pasivo circulante | N7: Activo circulante/pasivo circulante
B8: Importe | C8: % | D8: Importe | E8: % | F8: Importe | G8: % | H8: Importe | I8: % | K8: =B19/B61 | L8: =D19/D61 | M8: =F19/F61 | N8: =H19/H61
A9: CAJA | C9: =B9/$B$43 | E9: =D9/$D$43 | F9: ='2025'!H4 | G9: =F9/$F$43 | I9: =H9/$H$43
A10: BANCOS | C10: =B10/$B$43 | E10: =D10/$D$43 | F10: ='2025'!H5 | G10: =F10/$F$43 | I10: =H10/$H$43 | K10: Prueba del acido | L10: Prueba del acido | M10: Prueba del acido | N10: Prueba del acido
A11: CLIENTES | C11: =B11/$B$43 | E11: =D11/$D$43 | F11: ='2025'!H6 | G11: =F11/$F$43 | I11: =H11/$H$43 | K11: Activo circulantes-inventario/ Pasivos circulantes | L11: Activo circulantes-inventario/ Pasivos circulantes | M11: Activo circulantes-inventario/ Pasivos circulantes | N11: Activo circulantes-inventario/ Pasivos circulantes
A12: CUENTAS POR COBRAR | C12: =B12/$B$43 | E12: =D12/$D$43 | F12: ='2025'!H7 | G12: =F12/$F$43 | I12: =H12/$H$43 | K12: =(B19-B16)/B61 | L12: =(D19-D16)/D61 | M12: =(F19-F16)/F61 | N12: =(H19-H16)/H61
A13: DEUDORES DIVERSOS | C13: =B13/$B$43 | E13: =D13/$D$43 | F13: ='2025'!H8 | G13: =F13/$F$43 | I13: =H13/$H$43
A14: ISR DIFERIDO | C14: =B14/$B$43 | E14: =D14/$D$43 | F14: ='2025'!H9 | G14: =F14/$F$43 | I14: =H14/$H$43 | K14: Efectivo a pasivo circulante | L14: Efectivo a pasivo circulante | M14: Efectivo a pasivo circulante | N14: Efectivo a pasivo circulante
A15: IMPUESTOS A FAVOR | C15: =B15/$B$43 | E15: =D15/$D$43 | F15: ='2025'!H10 | G15: =F15/$F$43 | I15: =H15/$H$43 | K15: efectivo/pasivo circulate | L15: efectivo/pasivo circulate | M15: efectivo/pasivo circulate | N15: efectivo/pasivo circulate
A16: INVENTARIOS | C16: =B16/$B$43 | E16: =D16/$D$43 | F16: ='2025'!H11 | G16: =F16/$F$43 | I16: =H16/$H$43 | K16: =(B9+B10)/B61 | L16: =(D9+D10)/D61 | M16: =(F9+F10)/F61 | N16: =(H9+H10)/H61
A17: PAGOS ANTICIPADOS | C17: =B17/$B$43 | E17: =D17/$D$43 | F17: ='2025'!H12 | G17: =F17/$F$43 | I17: =H17/$H$43 | K17: B) ACTIVIDAD O ROTACIONES | L17: B) ACTIVIDAD O ROTACIONES | M17: B) ACTIVIDAD O ROTACIONES | N17: B) ACTIVIDAD O ROTACIONES
A18: ANTICIPO PROVEEDORES | C18: =B18/$B$43 | E18: =D18/$D$43 | F18: ='2025'!H13 | G18: =F18/$F$43 | I18: =H18/$H$43 | K18: Rotacion de cuentas por cobrar | L18: Rotacion de cuentas por cobrar | M18: Rotacion de cuentas por cobrar | N18: Rotacion de cuentas por cobrar
A19: Total - CIRCULANTE | B19: =SUM(B9:B18) | C19: =B19/$B$43 | D19: =SUM(D9:D18) | E19: =D19/$D$43 | F19: =SUM(F9:F18) | G19: =F19/$F$43 | H19: =SUM(H9:H18) | I19: =H19/$H$43 | K19: Ventas/Cuentas por cobrar ( Clientes) | L19: Ventas/Cuentas por cobrar ( Clientes) | M19: Ventas/Cuentas por cobrar ( Clientes) | N19: Ventas/Cuentas por cobrar ( Clientes)
K20: ='Edo de resultados'!B7/Balance!B11 | L20: ='Edo de resultados'!D7/Balance!D11 | M20: ='Edo de resultados'!F7/Balance!F11 | N20: ='Edo de resultados'!H7/Balance!H11 | O20: veces por año
B21: - - - - - - - - - - - - - | D21: - - - - - - - - - - - - - | F21: - - - - - - - - - - - - - | H21: - - - - - - - - - - - - -
K22: Periodo promedio de cobro | L22: Periodo promedio de cobro | M22: Periodo promedio de cobro | N22: Periodo promedio de cobro
A23: ACTIVO- FIJO | K23: 365/rotacion de cuentas por cobrar | L23: 365/rotacion de cuentas por cobrar | M23: 365/rotacion de cuentas por cobrar | N23: 365/rotacion de cuentas por cobrar
A24: EDIFICIOS | C24: =B24/$B$43 | E24: =D24/$D$43 | F24: ='2025'!H15 | G24: =F24/$F$43 | I24: =H24/$H$43 | K24: =365/K20 | L24: =365/L20 | M24: =365/M20 | N24: =365/N20 | O24: dias
A25: MAQ, Y EQU. | C25: =B25/$B$43 | E25: =D25/$D$43 | F25: ='2025'!H16 | G25: =F25/$F$43 | I25: =H25/$H$43
A26: EQ. TRANSPORTE | C26: =B26/$B$43 | E26: =D26/$D$43 | F26: ='2025'!H17 | G26: =F26/$F$43 | I26: =H26/$H$43 | K26: Rotacion de inventarios | L26: Rotacion de inventarios | M26: Rotacion de inventarios | N26: Rotacion de inventarios
A27: MOB. Y EQUIPO | C27: =B27/$B$43 | E27: =D27/$D$43 | F27: ='2025'!H18 | G27: =F27/$F$43 | I27: =H27/$H$43 | K27: costo de ventas/inventario | L27: costo de ventas/inventario | M27: costo de ventas/inventario | N27: costo de ventas/inventario
A28: EQU. COMPUTO | C28: =B28/$B$43 | E28: =D28/$D$43 | F28: ='2025'!H19 | G28: =F28/$F$43 | I28: =H28/$H$43 | K28: =('Edo de resultados'!B8/Balance!B16)*-1 | L28: =('Edo de resultados'!D8/Balance!D16)*-1 | M28: =('Edo de resultados'!F8/Balance!F16)*-1 | N28: =('Edo de resultados'!H8/Balance!H16)*-1 | O28: veces por año
A29: OTROS ACTIVOS | C29: =B29/$B$43 | E29: =D29/$D$43 | F29: ='2025'!H20 | G29: =F29/$F$43 | I29: =H29/$H$43
A30: TERRENOS | C30: =B30/$B$43 | E30: =D30/$D$43 | F30: ='2025'!H21 | G30: =F30/$F$43 | I30: =H30/$H$43 | K30: Dias de Inventario | L30: Dias de Inventario | M30: Dias de inventario | N30: Dias de inventario
A31: DEPRECIACION ACUMULADA(MENOS) | C31: =B31/$B$43 | E31: =D31/$D$43 | F31: ='2025'!H22 | G31: =F31/$F$43 | I31: =H31/$H$43 | K31: Dias del periodo/rotacion de inventarios | L31: Dias del periodo/rotacion de inventarios | M31: Dias del periodo/rotacion de inventarios | N31: Dias del periodo/rotacion de inventarios
K32: =365/K28 | L32: =365/L28 | M32: =365/M28 | N32: =365/N28 | O32: dias
A33: Total- FIJO | B33: =SUM(B24:B31) | C33: =B33/$B$43 | D33: =SUM(D24:D31) | E33: =D33/$D$43 | F33: =SUM(F24:F31) | G33: =F33/$F$43 | H33: =SUM(H24:H31) | I33: =H33/$H$43
B34: - - - - - - - - - - - - - | D34: - - - - - - - - - - - - - | F34: - - - - - - - - - - - - - | H34: - - - - - - - - - - - - - | K34: Rotacion de cuentas x pagar | L34: Rotacion de cuentas x pagar | M34: Rotacion de cuentas x pagar | N34: Rotacion de cuentas x pagar
K35: Costo de ventas / proveedores | L35: Costo de ventas / proveedores | M35: Costo de ventas / proveedores | N35: Costo de ventas / proveedores
A36: ACTIVO- DIFERIDO | K36: =('Edo de resultados'!B8/Balance!B52)*-1 | L36: =('Edo de resultados'!D8/Balance!D52)*-1 | M36: =('Edo de resultados'!F8/Balance!F52)*-1 | N36: =('Edo de resultados'!H8/Balance!H52)*-1 | O36: veces por año
A37: GASTOS DE INSTALACION | C37: =B37/$B$43 | E37: =D37/$D$43 | F37: ='2025'!H24 | G37: =F37/$F$43 | I37: =H37/$H$43 | K37: Periodo prom de pago DIAS de cuentas x pagar | L37: Periodo prom de pago DIAS de cuentas x pagar | M37: Periodo prom de pago DIAS de cuentas x pagar | N37: Periodo prom de pago DIAS de cuentas x pagar
A38: DEPOSITOS EN GARANTIA | C38: =B38/$B$43 | E38: =D38/$D$43 | F38: ='2025'!H25 | G38: =F38/$F$43 | I38: =H38/$H$43 | K38: 365/ rotacion de ctas x pagar | L38: 365/ rotacion de ctas x pagar | M38: 365/ rotacion de ctas x pagar | N38: 365/ rotacion de ctas x pagar
A39: OTROS ACTIVOS A LARGO PLAZO | C39: =B39/$B$43 | E39: =D39/$D$43 | F39: ='2025'!H26 | G39: =F39/$F$43 | I39: =H39/$H$43 | K39: =365/K36 | L39: =365/L36 | M39: =365/M36 | N39: =365/N36 | O39: dias
A40: Total- DIFERIDO | B40: =SUM(B37:B39) | C40: =B40/$B$43 | D40: =SUM(D37:D39) | E40: =D40/$D$43 | F40: =SUM(F37:F39) | G40: =F40/$F$43 | H40: =SUM(H37:H39) | I40: =H40/$H$43 | K40: C) ENDEUDAMIENTO | L40: C) ENDEUDAMIENTO | M40: C) ENDEUDAMIENTO | N40: C) ENDEUDAMIENTO
B41: - - - - - - - - - - - - - | D41: - - - - - - - - - - - - - | F41: - - - - - - - - - - - - - | H41: - - - - - - - - - - - - - | K41: Razon de endeudamiento ( PT/AT) | L41: Razon de endeudamiento ( PT/AT) | M41: Razon de endeudamiento ( PT/AT) | N41: Razon de endeudamiento ( PT/AT)
...

Sheet Edo de resultados
A1: =Balance!D1
A3: Estado de Resultados | B3: =Balance!B3 | D3: =B3+1 | F3: =D3+1 | H3: =F3+1&" "&"("&IF(K2=1,"enero",IF(K2=2,"febrero",IF(K2=3,"marzo",IF(K2=4,"abril",IF(K2=5,"mayo",IF(K2=6,"junio",IF(K2=7,"julio",IF(K2=8,"agosto",IF(K2=9,"septiembre",IF(K2=10,"octubre",IF(K2=11,"noviembre",IF(K2=12,"diciembre","INCORRECTO"))))))))))))&")" | J3: =F3+1&" "&"anualizado"
B4: Saldo | C4: % | D4: Saldo | E4: % | F4: Saldo | G4: % | H4: Saldo | I4: % | J4: Saldo | K4: %
A5: 40000000 - VENTAS
A6: menos bonificaciones o rebajas
A7: VENTAS | F7: ='2025'!H46 | J7: =(+H7/$K$2)*12
A8: COSTO DE VENTAS | C8: =(B8/$B$7)*-1 | E8: =(D8/$D$7)*-1 | F8: ='2025'!H47 | G8: =(F8/$F$7)*-1 | I8: =(H8/$H$7)*-1 | J8: =(+H8/$K$2)*12 | K8: =(J8/$J$7)*-1 | L8: CAPTURAR EN NEGATIVO PORQUE ES RESTA
A9: Utilidad Bruta | B9: =B7+B8 | C9: =B9/$B$7 | D9: =D7+D8 | E9: =D9/$D$7 | F9: =F7+F8 | G9: =F9/$F$7 | H9: =H7+H8 | I9: =H9/$H$7 | J9: =J7+J8 | K9: =J9/$J$7
A10: Gastos Generales | C10: =(B10/$B$7)*-1 | E10: =(D10/$D$7)*-1 | F10: ='2025'!H49 | G10: =(F10/$F$7)*-1 | I10: =(H10/$H$7)*-1 | J10: =(+H10/$K$2)*12 | K10: =(J10/$J$7)*-1 | L10: CAPTURAR EN NEGATIVO PORQUE ES RESTA
A11: Gastos de administración | C11: =(B11/$B$7)*-1 | E11: =(D11/$D$7)*-1 | F11: ='2025'!H50 | G11: =(F11/$F$7)*-1 | I11: =(H11/$H$7)*-1 | J11: =(+H11/$K$2)*12 | K11: =(J11/$J$7)*-1 | L11: CAPTURAR EN NEGATIVO PORQUE ES RESTA
A12: TOTAL GASTOS DE OPERACION | B12: =B10+B11 | C12: =(B12/$B$7)*-1 | D12: =D10+D11 | E12: =(D12/$D$7)*-1 | F12: =F10+F11 | G12: =(F12/$F$7)*-1 | H12: =H10+H11 | I12: =(H12/$H$7)*-1 | J12: =+J10+J11 | K12: =(J12/$J$7)*-1
A14: Utilidad de Operación(EBIT) | B14: =B9+B12 | C14: =B14/$B$7 | D14: =D9+D12 | E14: =D14/$D$7 | F14: =F9+F12 | G14: =F14/$F$7 | H14: =H9+H12 | I14: =H14/$H$7 | J14: =J9+J12 | K14: =J14/$J$7
A15: GASTOS FINANCIEROS(menos) | C15: =(B15/$B$7)*-1 | E15: =(D15/$D$7)*-1 | F15: ='2025'!H52 | G15: =(F15/$F$7)*-1 | I15: =(H15/$H$7)*-1 | J15: =(+H15/$K$2)*12 | K15: =(J15/$J$7)*-1 | L15: CAPTURAR EN NEGATIVO PORQUE ES RESTA
A16: PRODUCTOS FINANCIEROS(mas) | C16: =(B16/$B$7) | E16: =(D16/$D$7) | F16: ='2025'!H53 | G16: =(F16/$F$7) | I16: =(H16/$H$7) | J16: =(+H16/$K$2)*12 | K16: =(J16/$J$7)
A17: Utilidad/ perdida cambiaria | C17: =(B17/$B$7) | E17: =(D17/$D$7) | F17: ='2025'!H54 | G17: =(F17/$F$7) | I17: =(H17/$H$7) | J17: =(+H17/$K$2)*12 | K17: =(J17/$J$7)
A18: Total Financieros | B18: =B15+B16+B17 | C18: =(B18/$B$7)*-1 | D18: =D15+D16+D17 | E18: =(D18/$D$7)*-1 | F18: =F15+F16+F17 | G18: =(F18/$F$7)*-1 | H18: =H15+H16+H17 | I18: =(H18/$F$7)*-1 | J18: =J15+J16+J17 | K18: =(J18/$J$7)*-1
A19: Utilidad despues de intereses | B19: =B14+B18 | C19: =B19/$B$7 | D19: =D14+D18 | E19: =D19/$D$7 | F19: =F14+F18 | G19: =F19/$F$7 | H19: =H14+H18 | I19: =H19/$H$7 | J19: =J14+J18 | K19: =J19/$J$7
A20: OTROS GASTOS(menos) | C20: =B20/$B$7 | E20: =D20/$D$7 | F20: ='2025'!H56 | G20: =F20/$F$7 | I20: =H20/$H$7 | J20: =(+H20/$K$2)*12 | K20: =J20/$J$7 | L20: CAPTURAR EN NEGATIVO PORQUE ES RESTA
A21: OTROS INGRESOS(mas) | C21: =B21/$B$7 | E21: =D21/$D$7 | F21: ='2025'!H57 | G21: =F21/$F$7 | I21: =H21/$H$7 | J21: =(+H21/$K$2)*12 | K21: =J21/$J$7
A22: Utilidad antes de impuestos | B22: =B19+B20+B21 | C22: =B22/$B$7 | D22: =D19+D20+D21 | E22: =D22/$D$7 | F22: =F19+F20+F21 | G22: =F22/$F$7 | H22: =H19+H20+H21 | I22: =H22/$H$7 | J22: =J19+J20+J21 | K22: =J22/$J$7
A24: IMPUESTOS | C24: =(B24/$B$7)*-1 | E24: =(D24/$D$7)*-1 | F24: ='2025'!H59 | G24: =(F24/$F$7)*-1 | I24: =(H24/$H$7)*-1 | J24: =(+H24/$K$2)*12 | K24: =(J24/$J$7)*-1 | L24: CAPTURAR EN NEGATIVO PORQUE ES RESTA
A25: Utilidad Neta | B25: =B22+B24 | C25: =B25/$B$7 | D25: =D22+D24 | E25: =D25/$D$7 | F25: =F22+F24 | G25: =F25/$F$7 | H25: =H22+H24 | I25: =H25/$H$7 | J25: =J22+J24 | K25: =J25/$J$7
B26: ============= | D26: ============= | F26: ============= | H26: ============ | J26: ============
A29: DEPRECIACION | D29: =(+Balance!D31-Balance!B31)*-1 | F29: ='2025'!H61 | H29: =(+Balance!H31-Balance!F31)*-1 | J29: =(+H29/$K$2)*12 | L29: CAPTURARLA( ES LA DIFERENCIA ENTRE DEP ACUM DEL ULTIMO AÑO MENOS LA DEL AÑO ANTERIOR
A30: TOTAL EBITDA(UTIL DE OPER + DEP) | B30: =B29+B14 | D30: =D29+D14 | F30: =F29+F14 | H30: =H29+H14 | J30: =J29+J14 | L30: EBITDA

Sheet Flujo
B1: ESTADO DE FLUJO DE EFECTIVO | C1: =Balance!B3 | E1: =C1+1 | G1: =E1+1 | J1: Saldos en Balances Generales
B2: Flujo Operativo | C2: Saldos | D2: Totales | E2: Saldos | F2: Totales | G2: Saldos | H2: Totales | J2: =K2-1 | K2: =E1 | L2: =K2+1 | M2: =L2+1
B3: Utilidad neta | C3: =+'Edo de resultados'!D25 | E3: =+'Edo de resultados'!F25 | G3: =+'Edo de resultados'!H25 | K3: =C3 | L3: =E3 | M3: =G3
A4: * | B4: Depreciacion | C4: =J4-K4 | E4: =K4-L4 | G4: =L4-M4 | J4: =Balance!B31 | K4: =Balance!D31 | L4: =Balance!F31 | M4: =Balance!H31
A5: * | B5: Cambio en Clientes | C5: =J5-K5 | E5: =K5-L5 | G5: =L5-M5 | J5: =Balance!B11 | K5: =Balance!D11 | L5: =Balance!F11 | M5: =Balance!H11
A6: * | B6: Cambio en cuentas por cobrar | C6: =J6-K6 | E6: =K6-L6 | G6: =L6-M6 | J6: =Balance!B12 | K6: =Balance!D12 | L6: =Balance!F12 | M6: =Balance!H12
A7: * | B7: Cambio en Deudores Diversos | C7: =J7-K7 | E7: =K7-L7 | G7: =L7-M7 | J7: =Balance!B13 | K7: =Balance!D13 | L7: =Balance!F13 | M7: =Balance!H13
B8: Cambio en ISR Diferido | C8: =J8-K8 | E8: =K8-L8 | G8: =L8-M8 | J8: =Balance!B14 | K8: =Balance!D14 | L8: =Balance!F14 | M8: =Balance!H14
B9: Cambio en Impuestos a favor | C9: =J9-K9 | E9: =K9-L9 | G9: =L9-M9 | J9: =Balance!B15 | K9: =Balance!D15 | L9: =Balance!F15 | M9: =Balance!H15
B10: Cambio en Inventarios | C10: =J10-K10 | E10: =K10-L10 | G10: =L10-M10 | J10: =Balance!B16 | K10: =Balance!D16 | L10: =Balance!F16 | M10: =Balance!H16
B11: Cambio en Anticipo a Proveedores | C11: =J11-K11 | E11: =K11-L11 | G11: =L11-M11 | J11: =Balance!B18 | K11: =Balance!D18 | L11: =Balance!F18 | M11: =Balance!H18
B12: Cambio en Otros Activos no Circulantes | C12: =J12-K12 | E12: =K12-L12 | G12: =L12-M12 | J12: =+Balance!B40 | K12: =+Balance!D40 | L12: =+Balance!F40 | M12: =+Balance!H40
A13: * | B13: Cambio en Compañías Afiliadas (Activo) | C13: =J13-K13 | E13: =K13-L13 | G13: =L13-M13 | J13: =Balance!B17 | K13: =Balance!D17 | L13: =Balance!F17 | M13: =Balance!H17
A14: * | B14: Cambio en Proveedores | C14: =K14-J14 | E14: =L14-K14 | G14: =M14-L14 | J14: =Balance!B52 | K14: =Balance!D52 | L14: =Balance!F52 | M14: =Balance!H52
B15: Cambio en Pagos Anticipados | C15: =K15-J15 | E15: =L15-K15 | G15: =M15-L15 | J15: =Balance!B55 | K15: =Balance!D55 | L15: =Balance!F55 | M15: =Balance!H55
B16: Cambio en impuestos por pagar | C16: =K16-J16 | E16: =L16-K16 | G16: =M16-L16 | J16: =Balance!B56 | K16: =Balance!D56 | L16: =Balance!F56 | M16: =Balance!H56
B17: Cambio en Acreedores Diversos | C17: =K17-J17 | E17: =L17-K17 | G17: =M17-L17 | J17: =+Balance!B54 | K17: =+Balance!D54 | L17: =+Balance!F54 | M17: =+Balance!H54
A18: * | B18: Cambio en Anticipo de clientes | C18: =K18-J18 | E18: =L18-K18 | G18: =M18-L18 | J18: =+Balance!B57 | K18: =+Balance!D57 | L18: =+Balance!F57 | M18: =+Balance!H57
B19: Cambio en otras cuentas por pagar LP | C19: =K19-J19 | E19: =L19-K19 | G19: =M19-L19 | J19: =+Balance!B65 | K19: =+Balance!D65 | L19: =+Balance!F65 | M19: =+Balance!H65
B20: Ajustes por dictamen | C20: =K20-J20 | E20: =L20-K20 | G20: =M20-L20 | J20: =+Balance!B66
B22: Efectivo de actividades operativas | D22: =SUM(C3:C21) | F22: =SUM(E3:E21) | H22: =SUM(G3:G21)
B24: Flujo de Inversion
B25: Cambio en Edificios | C25: =J25-K25 | E25: =K25-L25 | G25: =L25-M25 | J25: =+Balance!B24 | K25: =+Balance!D24 | L25: =+Balance!F24 | M25: =+Balance!H24
B26: Cambio en Maq. y Eq. Transporte | C26: =J26-K26 | E26: =K26-L26 | G26: =L26-M26 | J26: =+Balance!B25 | K26: =+Balance!D25 | L26: =+Balance!F25 | M26: =+Balance!H25
B27: Cambio en Equipo Transporte | C27: =J27-K27 | E27: =K27-L27 | G27: =L27-M27 | J27: =+Balance!B26 | K27: =+Balance!D26 | L27: =+Balance!F26 | M27: =+Balance!H26
B28: Cambio en Mob y Equ | C28: =J28-K28 | E28: =K28-L28 | G28: =L28-M28 | J28: =+Balance!B27 | K28: =+Balance!D27 | L28: =+Balance!F27 | M28: =+Balance!H27
B29: Cambio en Eq. Computo | C29: =J29-K29 | E29: =K29-L29 | G29: =L29-M29 | J29: =+Balance!B28 | K29: =+Balance!D28 | L29: =+Balance!F28 | M29: =+Balance!H28
B30: Cambio en Otros Activos | C30: =J30-K30 | E30: =K30-L30 | G30: =L30-M30 | J30: =+Balance!B29 | K30: =+Balance!D29 | L30: =+Balance!F29 | M30: =+Balance!H29
B31: Cambio en Terrenos | C31: =J31-K31 | E31: =K31-L31 | G31: =L31-M31 | J31: =+Balance!B30 | K31: =+Balance!D30 | L31: =+Balance!F30 | M31: =+Balance!H30
B32: Efectivo de actividades Inversion | D32: =SUM(C25:C31) | F32: =SUM(E25:E31) | H32: =SUM(G25:G31)
B34: Flujo de financiamiento
B35: Cambio en documentos por pagar CP | C35: =K35-J35 | E35: =L35-K35 | G35: =M35-L35 | J35: =+Balance!B53 | K35: =+Balance!D53 | L35: =+Balance!F53 | M35: =+Balance!H53
B36: Cambio en documentos por pagar LP | C36: =K36-J36 | E36: =L36-K36 | G36: =M36-L36 | J36: =+Balance!B64 | K36: =+Balance!D64 | L36: =+Balance!F64 | M36: =+Balance!H64
B37: Cambio en capital Pagado | C37: =K37-J37 | E37: =L37-K37 | G37: =M37-L37 | J37: =Balance!B74 | K37: =Balance!D74 | L37: =Balance!F74 | M37: =+Balance!H74
B38: Cambio Otros Rdos Integrales | C38: =K38-J38 | E38: =L38-K38 | G38: =M38-L38 | J38: =+Balance!B76 | K38: =+Balance!D76 | L38: =+Balance!F76 | M38: =+Balance!H76
B39: Dividendos decretados | C39: =K39-J39 | E39: =L39-K39 | G39: =M39-L39
B40: Diferencia en Rdo ej anteriores | C40: =K40-J40 | E40: =L40-K40 | G40: =M40-L40 | J40: =-Balance!D77+Balance!B77+Balance!B78 | K40: =IFERROR(+Balance!E77-Balance!C77-Balance!C78,0) | L40: =+Balance!F77-Balance!D77-Balance!D78 | M40: =+Balance!H77-Balance!F77-Balance!F78+L40
B41: Rdo 2021 | C41: =K41-J41 | E41: =L41-K41 | G41: =M41-L41
B44: Efectivo de actividades Financiamiento | D44: =SUM(C35:C42) | F44: =SUM(E35:E42) | H44: =SUM(G35:G42)
B46: Aumento/disminución en efectivo | D46: =SUM(D22:D44) | F46: =SUM(F22:F44) | H46: =SUM(H22:H44)
...

Sheet Edo de res AN HORIZ
A1: =Balance!D1 | M1: AÑO 1 VS AÑO 2 | Q1: AÑO 2 VS AÑO 3 | U1: AÑO 3 VS AÑO 4
K2: ='Edo de resultados'!K2 | M2: ANALISIS HORIZONTAL | Q2: ANALISIS HORIZONTAL | U2: ANALISIS HORIZONTAL
A3: Estado de Resultados | B3: ='Edo de resultados'!B3:C3 | D3: ='Edo de resultados'!D3:E3 | F3: ='Edo de resultados'!F3:G3 | H3: ='Edo de resultados'!H3:I3 | J3: ='Edo de resultados'!J3:K3 | M3: VARIACION $ | N3: VARIACION % | O3: INDICES | Q3: VARIACION $ | R3: VARIACION % | S3: INDICES | U3: VARIACION $ | V3: VARIACION % | W3: INDICES
A4: VENTAS | B4: ='Edo de resultados'!B7 | D4: ='Edo de resultados'!D7 | F4: ='Edo de resultados'!F7 | H4: ='Edo de resultados'!H7 | J4: =+(H4/$K$2)*12 | M4: =+D4-B4 | N4: =M4/B4 | O4: =D4/B4 | Q4: =F4-D4 | R4: =Q4/D4 | S4: =F4/D4 | U4: =H4-F4 | V4: =U4/F4 | W4: =H4/F4
A5: COSTO DE VENTAS | B5: ='Edo de resultados'!B8 | C5: =B5/B$4 | D5: ='Edo de resultados'!D8 | E5: =D5/D$4 | F5: ='Edo de resultados'!F8 | G5: =F5/F$4 | H5: ='Edo de resultados'!H8 | I5: =H5/H$4 | J5: =+(H5/$K$2)*12 | K5: =J5/J$4 | M5: =+D5-B5 | N5: =M5/B5 | O5: =D5/B5 | Q5: =F5-D5 | R5: =Q5/D5 | S5: =F5/D5 | U5: =H5-F5 | V5: =U5/F5 | W5: =H5/F5
A6: Utilidad Bruta | B6: =B4+B5 | C6: =B6/B$4 | D6: =D4+D5 | E6: =D6/D$4 | F6: =F4+F5 | G6: =F6/F$4 | H6: =H4+H5 | I6: =H6/H$4 | J6: =J4+J5 | K6: =J6/J$4 | M6: =+D6-B6 | N6: =M6/B6 | O6: =D6/B6 | Q6: =F6-D6 | R6: =Q6/D6 | S6: =F6/D6 | U6: =H6-F6 | V6: =U6/F6 | W6: =H6/F6
A7: GASTOS DE OPERACION | B7: ='Edo de resultados'!B12 | C7: =B7/B$4 | D7: ='Edo de resultados'!D12 | E7: =D7/D$4 | F7: ='Edo de resultados'!F12 | G7: =F7/F4 | H7: ='Edo de resultados'!H12 | I7: =H7/H4 | J7: =+(H7/$K$2)*12 | K7: =J7/J4 | M7: =+D7-B7 | N7: =M7/B7 | O7: =D7/B7 | Q7: =F7-D7 | R7: =Q7/D7 | S7: =F7/D7 | U7: =H7-F7 | V7: =U7/F7 | W7: =H7/F7
A8: Utilidad de Operación(EBIT) | B8: ='Edo de resultados'!B14 | C8: =B8/B$4 | D8: ='Edo de resultados'!D14 | E8: =D8/D$4 | F8: ='Edo de resultados'!F14 | G8: =F8/F$4 | H8: ='Edo de resultados'!H14 | I8: =H8/H$4 | J8: =+J6+J7 | K8: =J8/J$4 | M8: =+D8-B8 | N8: =M8/B8 | O8: =D8/B8 | Q8: =F8-D8 | R8: =Q8/D8 | S8: =F8/D8 | U8: =H8-F8 | V8: =U8/F8 | W8: =H8/F8
A9: GASTOS FINANCIEROS/PRODUCTOS | B9: ='Edo de resultados'!B18 | C9: =B9/B$4 | D9: ='Edo de resultados'!D18 | E9: =D9/D$4 | F9: ='Edo de resultados'!F18 | G9: =F9/F$4 | H9: ='Edo de resultados'!H18 | I9: =H9/H$4 | J9: =+(H9/$K$2)*12 | K9: =J9/J$4 | M9: =+D9-B9 | N9: =M9/B9 | O9: =D9/B9 | Q9: =F9-D9 | R9: =Q9/D9 | S9: =F9/D9 | U9: =H9-F9 | V9: =U9/F9 | W9: =H9/F9
A10: OTROS GASTOS/PRODUCTOS | B10: ='Edo de resultados'!B20+'Edo de resultados'!B21 | C10: =B10/B$4 | D10: ='Edo de resultados'!D20+'Edo de resultados'!D21 | E10: =D10/D$4 | F10: ='Edo de resultados'!F20+'Edo de resultados'!F21 | G10: =F10/F$4 | H10: ='Edo de resultados'!H20+'Edo de resultados'!H21 | J10: =+(H10/$K$2)*12
A11: Utilidad antes de impuestos | B11: ='Edo de resultados'!B22 | C11: =B11/B$4 | D11: ='Edo de resultados'!D22 | E11: =D11/D$4 | F11: ='Edo de resultados'!F22 | G11: =F11/F$4 | H11: ='Edo de resultados'!H22 | I11: =H11/H$4 | J11: =+J8+J9 | K11: =J11/J$4 | M11: =+D11-B11 | N11: =M11/B11 | O11: =D11/B11 | Q11: =F11-D11 | R11: =Q11/D11 | S11: =F11/D11 | U11: =H11-F11 | V11: =U11/F11 | W11: =H11/F11
A12: IMPUESTOS | B12: ='Edo de resultados'!B24 | C12: =B12/B$4 | D12: ='Edo de resultados'!D24 | E12: =D12/D$4 | F12: ='Edo de resultados'!F24 | G12: =F12/F$4 | H12: ='Edo de resultados'!H24 | I12: =H12/H$4 | K12: =J12/J$4 | M12: =+D12-B12 | N12: =M12/B12 | O12: =D12/B12 | Q12: =F12-D12 | R12: =Q12/D12 | S12: =F12/D12 | U12: =H12-F12 | V12: =U12/F12 | W12: =H12/F12
A13: Utilidad Neta | B13: ='Edo de resultados'!B25 | C13: =B13/B$4 | D13: ='Edo de resultados'!D25 | E13: =D13/D$4 | F13: ='Edo de resultados'!F25 | G13: =F13/F$4 | H13: ='Edo de resultados'!H25 | I13: =H13/H$4 | J13: =+J11+J12 | K13: =J13/J$4 | M13: =+D13-B13 | N13: =M13/B13 | O13: =D13/B13 | Q13: =F13-D13 | R13: =Q13/D13 | S13: =F13/D13 | U13: =H13-F13 | V13: =U13/F13 | W13: =H13/F13
N18: ACTIVO | R18: ACTIVO | V18: ACTIVO
A19: ACTIVO | M19: AÑO 1 VS AÑO 2 | Q19: AÑO 2 VS AÑO 3 | T19: CIRCULANTE | U19: AÑO 3 VS AÑO 4
A20: ACTIVO- CIRCULANTE | B20: Analisis vertical | D20: Analisis vertical | F20: Analisis vertical | H20: Analisis vertical | M20: ANALISIS HORIZONTAL | Q20: ANALISIS HORIZONTAL | U20: ANALISIS HORIZONTAL
B21: Importe | C21: % | D21: Importe | E21: % | F21: Importe | G21: % | H21: Importe | I21: % | M21: VARIACION $ | N21: VARIACION % | O21: INDICES | Q21: VARIACION $ | R21: VARIACION % | S21: INDICES | U21: VARIACION $ | V21: VARIACION % | W21: INDICES
A22: CAJA | B22: =Balance!B9 | C22: =B22/$B$56 | D22: =Balance!D9 | E22: =D22/$D$56 | F22: =Balance!F9 | G22: =F22/$F$56 | H22: =Balance!H9 | I22: =H22/$H$56 | M22: =D22-B22 | N22: =M22/B22 | O22: =D22/B22 | Q22: =F22-D22 | R22: =Q22/D22 | S22: =F22/D22 | U22: =H22-F22 | V22: =U22/F22 | W22: =H22/F22
A23: BANCOS | B23: =Balance!B10 | C23: =B23/$B$56 | D23: =Balance!D10 | E23: =D23/$D$56 | F23: =Balance!F10 | G23: =F23/$F$56 | H23: =Balance!H10 | I23: =H23/$H$56 | M23: =D23-B23 | N23: =M23/B23 | O23: =D23/B23 | Q23: =F23-D23 | R23: =Q23/D23 | S23: =F23/D23 | U23: =H23-F23 | V23: =U23/F23 | W23: =H23/F23
A24: CLIENTES | B24: =Balance!B11 | C24: =B24/$B$56 | D24: =Balance!D11 | E24: =D24/$D$56 | F24: =Balance!F11 | G24: =F24/$F$56 | H24: =Balance!H11 | I24: =H24/$H$56 | M24: =D24-B24 | N24: =M24/B24 | O24: =D24/B24 | Q24: =F24-D24 | R24: =Q24/D24 | S24: =F24/D24 | U24: =H24-F24 | V24: =U24/F24 | W24: =H24/F24
A25: INVENTARIO | B25: =Balance!B16 | C25: =B25/$B$56 | D25: =Balance!D16 | E25: =D25/$D$56 | F25: =Balance!F16 | G25: =F25/$F$56 | H25: =Balance!H16 | I25: =H25/$H$56 | M25: =D25-B25 | N25: =M25/B25 | O25: =D25/B25 | Q25: =F25-D25 | R25: =Q25/D25 | S25: =F25/D25 | U25: =H25-F25 | V25: =U25/F25 | W25: =H25/F25
A26: DEUDORES DIVERSOS | B26: =Balance!B13 | C26: =B26/$B$56 | D26: =Balance!D13 | E26: =D26/$D$56 | F26: =Balance!F13 | G26: =F26/$F$56 | H26: =Balance!H13 | I26: =H26/$H$56 | M26: =D26-B26 | N26: =M26/B26 | O26: =D26/B26 | Q26: =F26-D26 | R26: =Q26/D26 | S26: =F26/D26 | U26: =H26-F26 | V26: =U26/F26 | W26: =H26/F26
A27: OTRAS CUENTAS POR COBRAR | B27: =+Balance!B14+Balance!B12 | C27: =B27/$B$56 | D27: =+Balance!D14+Balance!D12 | E27: =D27/$D$56 | F27: =+Balance!F14+Balance!F12 | G27: =F27/$F$56 | H27: =+Balance!H14+Balance!H12 | I27: =H27/$H$56 | M27: =D27-B27 | N27: =M27/B27 | O27: =D27/B27 | Q27: =F27-D27 | R27: =Q27/D27 | S27: =F27/D27 | U27: =H27-F27 | V27: =U27/F27 | W27: =H27/F27
A28: IVA POR RECUPERAR | B28: =Balance!B15 | C28: =B28/$B$56 | D28: =Balance!D15 | E28: =D28/$D$56 | F28: =Balance!F15 | G28: =F28/$F$56 | H28: =Balance!H15 | I28: =H28/$H$56 | M28: =D28-B28 | N28: =M28/B28 | O28: =D28/B28 | Q28: =F28-D28 | R28: =Q28/D28 | S28: =F28/D28 | U28: =H28-F28 | V28: =U28/F28 | W28: =H28/F28
A29: OTROS ACTIVOS | B29: =Balance!B17+Balance!B18 | C29: =B29/$B$56 | D29: =Balance!D17+Balance!D18 | E29: =D29/$D$56 | F29: =Balance!F17+Balance!F18 | G29: =F29/$F$56 | H29: =Balance!H17+Balance!H18 | I29: =H29/$H$56 | M29: =D29-B29 | N29: =M29/B29 | O29: =D29/B29 | Q29: =F29-D29 | R29: =Q29/D29 | S29: =F29/D29 | U29: =H29-F29 | V29: =U29/F29 | W29: =H29/F29
A32: Total - CIRCULANTE | B32: =SUM(B22:B31) | C32: =B32/$B$56 | D32: =SUM(D22:D31) | E32: =D32/$D$56 | F32: =SUM(F22:F31) | G32: =F32/$F$56 | H32: =SUM(H22:H31) | I32: =H32/$H$56 | M32: =D32-B32 | N32: =M32/B32 | O32: =D32/B32 | Q32: =F32-D32 | R32: =Q32/D32 | S32: =F32/D32 | U32: =H32-F32 | V32: =U32/F32 | W32: =H32/F32
B34: - - - - - - - - - - - - - | F34: - - - - - - - - - - - - - | H34: - - - - - - - - - - - - -
A36: ACTIVO- FIJO | N36: ACTIVO- FIJO | R36: ACTIVO- FIJO | V36: ACTIVO- FIJO
A37: EDIFICIOS | B37: =Balance!B24 | C37: =B37/$B$56 | D37: =Balance!D24 | E37: =D37/$D$56 | F37: =Balance!F24 | G37: =F37/$F$43 | H37: =+Balance!H24 | I37: =H37/$H$56 | M37: =D37-B37 | N37: =M37/B37 | O37: =D37/B37 | Q37: =F37-D37 | R37: =Q37/D37 | S37: =F37/D37 | U37: =H37-F37 | V37: =U37/F37 | W37: =H37/F37
A38: MAQ, Y EQU. TRANSPORTE | B38: =Balance!B25 | C38: =B38/$B$56 | D38: =Balance!D25 | E38: =D38/$D$56 | F38: =Balance!F25 | G38: =F38/$F$43 | H38: =+Balance!H25 | I38: =H38/$H$56 | M38: =D38-B38 | N38: =M38/B38 | O38: =D38/B38 | Q38: =F38-D38 | R38: =Q38/D38 | S38: =F38/D38 | U38: =H38-F38 | V38: =U38/F38 | W38: =H38/F38
A39: EQUIPO DE TRANSPORTE | B39: =Balance!B26 | C39: =B39/$B$56 | D39: =Balance!D26 | E39: =D39/$D$56 | F39: =Balance!F26 | G39: =F39/$F$43 | H39: =+Balance!H26 | I39: =H39/$H$56 | M39: =D39-B39 | N39: =M39/B39 | O39: =D39/B39 | Q39: =F39-D39 | R39: =Q39/D39 | S39: =F39/D39 | U39: =H39-F39 | V39: =U39/F39 | W39: =H39/F39
A40: EQUIPO DE OFICINA | B40: =Balance!B27 | C40: =B40/$B$56 | D40: =Balance!D27 | E40: =D40/$D$56 | F40: =Balance!F27 | G40: =F40/$F$43 | H40: =+Balance!H27 | I40: =H40/$H$56 | M40: =D40-B40 | N40: =M40/B40 | O40: =D40/B40 | Q40: =F40-D40 | R40: =Q40/D40 | S40: =F40/D40 | U40: =H40-F40 | V40: =U40/F40 | W40: =H40/F40
A41: EQUIPO DE COMPUTO | B41: =Balance!B28 | C41: =B41/$B$56 | D41: =Balance!D28 | E41: =D41/$D$56 | F41: =Balance!F28 | G41: =F41/$F$43 | H41: =+Balance!H28 | I41: =H41/$H$56 | M41: =D41-B41 | N41: =M41/B41 | O41: =D41/B41 | Q41: =F41-D41 | R41: =Q41/D41 | S41: =F41/D41 | U41: =H41-F41 | V41: =U41/F41 | W41: =H41/F41
A42: OTROS UTILES | B42: =Balance!B29 | C42: =B42/$B$56 | D42: =Balance!D29 | E42: =D42/$D$56 | F42: =Balance!F29 | G42: =F42/$F$43 | H42: =+Balance!H29 | I42: =H42/$H$56 | M42: =D42-B42 | N42: =M42/B42 | O42: =D42/B42 | Q42: =F42-D42 | R42: =Q42/D42 | S42: =F42/D42 | U42: =H42-F42 | V42: =U42/F42 | W42: =H42/F42
B43: =Balance!B30 | C43: =B43/$B$56 | D43: =Balance!D30 | E43: =D43/$D$56 | F43: =Balance!F30 | G43: =F43/$F$43 | H43: =+Balance!H30 | I43: =H43/$H$56 | M43: =D43-B43 | N43: =M43/B43 | O43: =D43/B43 | Q43: =F43-D43 | R43: =Q43/D43 | S43: =F43/D43 | U43: =H43-F43 | V43: =U43/F43 | W43: =H43/F43
A44: DEPRECIACION ACUMULADA(MENOS) | B44: =Balance!B31 | C44: =B44/$B$56 | D44: =Balance!D31 | E44: =D44/$D$56 | F44: =Balance!F31 | G44: =F44/$F$43 | H44: =Balance!H31 | I44: =H44/$H$56 | M44: =D44-B44 | N44: =M44/B44 | O44: =D44/B44 | Q44: =F44-D44 | R44: =Q44/D44 | S44: =F44/D44 | U44: =H44-F44 | V44: =U44/F44 | W44: =H44/F44
A46: Total- FIJO | B46: =SUM(B37:B44) | C46: =B46/$B$56 | D46: =SUM(D37:D44) | E46: =D46/$D$56 | F46: =SUM(F37:F44) | G46: =F46/$F$56 | H46: =SUM(H37:H44) | I46: =H46/$H$56 | M46: =D46-B46 | N46: =M46/B46 | O46: =D46/B46 | Q46: =F46-D46 | R46: =Q46/D46 | S46: =F46/D46 | U46: =H46-F46 | V46: =U46/F46 | W46: =H46/F46
B47: - - - - - - - - - - - - - | F47: - - - - - - - - - - - - - | H47: - - - - - - - - - - - - -
A49: ACTIVO- DIFERIDO | N49: DIFERIDO | R49: DIFERIDO | V49: DIFERIDO
A50: PAGOS ANTICIPADOS | B50: =Balance!B37 | C50: =B50/$B$56 | D50: =Balance!D37 | E50: =D50/$D$56 | F50: =Balance!F37 | G50: =F50/$F$43 | H50: =Balance!H37 | I50: =H50/$H$43 | M50: =D50-B50 | N50: =M50/B50 | O50: =D50/B50 | Q50: =F50-D50 | R50: =Q50/D50 | S50: =F50/D50 | U50: =H50-F50 | V50: =U50/F50 | W50: =H50/F50
...

Sheet input
B2: =Balance!F3 | C2: =Balance!H3
A3: TOTAL ACTIVOS CIRCULANTES | B3: =Balance!F19 | C3: =Balance!H19
A4: TOTAL ACTIVOS FIJOS | B4: =Balance!F33 | C4: =Balance!H33
A5: TOTAL ACTIVOS DIFERIDOS | B5: =Balance!F40 | C5: =Balance!H40
A6: TOTAL PASIVO NO FINANCIERO | B6: =Balance!F61-Balance!F53 | C6: =Balance!H61-Balance!H53
A7: TOTAL PASIVO FINANCIERO | B7: =Balance!F53+Balance!F65 | C7: =Balance!H53+Balance!H65
A8: TOTAL PASIVO DIFERIDO | B8: =Balance!F67-Balance!F65 | C8: =Balance!H67-Balance!H65
A9: CXP Proveedores | B9: =Balance!F52 | C9: =Balance!H52
A10: CAPITAL CONTABLE TOTAL | B10: =Balance!F82 | C10: =Balance!H82
A12: VENTAS | B12: ='Edo de resultados'!F7 | C12: ='Edo de resultados'!H7
A13: UTILIDAD DE OPERACIÓN (Antes de impuestos y gastos financieros | B13: ='Edo de resultados'!F14 | C13: ='Edo de resultados'!H14
A14: DEPRECIACIÓN (edo. de resúltados) | B14: ='Edo de resultados'!F29 | C14: ='Edo de resultados'!H29

Sheet 2025
A1: Cuenta Extraída | B1: Monto Extraído | C1: Página | D1: Evidencia Visual | E1: Input / Ajuste | G1: Concepto | H1: Importe (Input)
G2: ── BALANCE ──
G3: ACTIVO CIRCULANTE
G4: Caja
G5: Bancos
G6: Clientes
G7: Cuentas Por Cobrar
G8: Deudores Diversos
G9: Isr Diferido
G10: Impuestos A Favor
G11: Inventarios
G12: Pagos Anticipados
G13: Anticipo Proveedores
... G61: Depreciacion
