Workbook
Name \0: #REF!
Name \C: #REF!
Name __xlnm._FilterDatabase: sectores!$D$1:$H$1069
Name AA: #REF!
Name AÑO: #REF!
Name AS2DocOpenMode: "AS2DocumentEdit"
Name BB: #REF!
Name CAPTURA: #REF!
Name CC: #REF!
Name DD: #REF!
Name depreciacion_last_partial_anualizado: DATOS!$U$11
Name depreciacion_PL_full_year: DATOS!$O$11
Name depreciacion_PL_last_partial: DATOS!$S$11
Name DOCXPAG: #N/A
Name EE: #REF!
Name EMP: #REF!
Name Excel_BuiltIn_Print_Area_5_1: CALIF!$A$1:$K$79
Name Excel_BuiltIn_Print_Area_5_1_3: Hoja10!$A$1:$K$79
Name FF: #REF!
Name IMPRESION: #REF!
Name INDICES: #REF!
Name INTACUMUL: #N/A
Name MENU: #REF!
Name MES: #REF!
Name nuevosca: #REF!
Name pagos_arrendamiento_mensual_full_year: DATOS!$O$13
Name PERDCAMBIOS: #N/A
Name rating_buro: DATOS!$Q$29
Name S.DEP: #REF!
Name SHARED_FORMULA_0: #N/A
Name SHARED_FORMULA_1: #N/A
Name SHARED_FORMULA_10: #N/A
Name SHARED_FORMULA_11: #N/A
Name SHARED_FORMULA_12: #N/A
Name SHARED_FORMULA_13: #N/A
Name SHARED_FORMULA_14: #N/A
Name SHARED_FORMULA_15: #N/A
Name SHARED_FORMULA_16: #N/A
Name SHARED_FORMULA_17: #N/A
Name SHARED_FORMULA_18: #N/A
Name SHARED_FORMULA_19: #N/A
Name SHARED_FORMULA_2: #N/A
Name SHARED_FORMULA_20: #N/A
Name SHARED_FORMULA_21: #N/A
Name SHARED_FORMULA_22: #N/A
Name SHARED_FORMULA_23: #N/A
Name SHARED_FORMULA_24: #N/A
Name SHARED_FORMULA_25: #N/A
Name SHARED_FORMULA_26: #N/A
Name SHARED_FORMULA_27: #N/A
Name SHARED_FORMULA_28: #N/A
Name SHARED_FORMULA_29: #N/A
Name SHARED_FORMULA_3: #N/A
Name SHARED_FORMULA_30: #N/A
Name SHARED_FORMULA_31: #N/A
Name SHARED_FORMULA_32: #N/A
Name SHARED_FORMULA_33: #N/A
Name SHARED_FORMULA_34: #N/A
Name SHARED_FORMULA_35: #N/A
Name SHARED_FORMULA_36: #N/A

Sheet Bal
E6: 2007 | F6: % | G6: 2008 | H6: % | I6: Jun - | J6: 2009 | K6: %
B8: BALANCE GENERAL
B9: ACTIVO CIRCULANTE
B11: Caja y Bancos | E11: 61506 | G11: 0.02 | H11: 271489 | I11: 0.05 | J11: 152319 | K11: 0.03
B12: Cuentas por Cobrar | E12: 805016 | G12: 0.21 | H12: 696737 | I12: 0.13 | J12: 590149 | K12: 0.11
B13: Deudores Diversos | E13: 696040 | G13: 0.18 | H13: 2303156 | I13: 0.41 | J13: 2475063 | K13: 0.45
B14: Inventarios | E14: 121292 | G14: 0.03 | H14: 199339 | I14: 0.04 | J14: 290010 | K14: 0.05
E15: 1683854 | G15: 0.44 | H15: 3470721 | I15: 0.63 | J15: 3507541 | K15: 0.64
B16: ACTIVO FIJO
B18: Terrenos y Edificios | E18: 287684 | G18: 0.07 | H18: 287684 | I18: 0.05 | J18: 287685 | K18: 0.05
B19: Maquinaria y Equipo | E19: 1960982 | G19: 0.5 | H19: 2362142 | I19: 0.42 | J19: 2425191 | K19: 0.44
B20: Muebles y Enseres | E20: 287942 | G20: 0.07 | H20: 398840 | I20: 0.07 | J20: 430042 | K20: 0.08
B21: Equipo de Transporte | E21: 44065 | G21: 0.01 | H21: 47054 | I21: 0.01 | J21: 54529 | K21: 0.01
B22: Depreciacion Acumulada | E22: -1014568 | G22: -0.26 | H22: -1181927 | I22: -0.21 | J22: -1274663 | K22: -0.23
E23: 1566105 | G23: 0.39 | H23: 1913793 | I23: 0.34 | J23: 1922784 | K23: 0.35
B24: ACTIVO DIFERIDO
B26: Pagos Anticipados | E26: 20318 | G26: 0.01 | H26: 41904 | I26: 0.01 | K26: 0
B27: Cargos Diferidos | E27: 630957 | G27: 0.16 | H27: 144259 | I27: 0.03 | J27: 34134 | K27: 0.01
B28: Inversiones en Valores | E28: 500 | G28: 0 | H28: 500 | I28: 0 | K28: 0
E29: 651775 | G29: 0.17 | H29: 186663 | I29: 0.04 | J29: 34134 | K29: 0.01
B30: TOTAL DE ACTIVO | E30: 3901734 | G30: 1 | H30: 5571177 | I30: 1 | J30: 5464459 | K30: 1
B31: PASIVO CIRCULANTE
B33: Proveedores | E33: 44762 | G33: 0.01 | H33: 30461 | I33: 0.01 | J33: 25632 | K33: 0
B34: Creditos a Corto Plazo | E34: 1035327 | G34: 0.27 | H34: 1588080 | I34: 0.29 | J34: 1000179 | K34: 0.18
B35: Impuestos a Pagar | E35: 85415 | G35: 0.02 | H35: 116008 | I35: 0.02 | J35: 52581 | K35: 0.01
B36: Acreedores Diversos | E36: 34072 | G36: 0.01 | H36: 720635 | I36: 0.13 | J36: 902103 | K36: 0.17
E37: 1199576 | G37: 0.31 | H37: 2455184 | I37: 0.45 | J37: 1980495 | K37: 0.36
B38: PASIVO A LARGO PLAZO
B40: Creditos a Largo Plazo | E40: 777045 | G40: 0.2 | H40: 659414 | I40: 0.12 | J40: 649505 | K40: 0.12
E41: 777045 | G41: 0.2 | H41: 659414 | I41: 0.12 | J41: 649505 | K41: 0.12
B44: TOTAL DE PASIVO | E44: 1976621 | G44: 0.51 | H44: 3114598 | I44: 0.57 | J44: 2630000 | K44: 0.48
B45: CAPITAL CONTABLE
B47: Capital Social | E47: 800000 | G47: 0.21 | H47: 800000 | I47: 0.14 | J47: 800000 | K47: 0.15
B48: Reservas | E48: 33328 | G48: 0.01 | H48: 54296 | I48: 0.01 | J48: 80869 | K48: 0.01
B49: Utilidad Acumulada | E49: 618232 | G49: 0.16 | H49: 1016623 | I49: 0.18 | J49: 1521517 | K49: 0.28
B50: Superavit por Reevaluacion | E50: 54194 | G50: 0.01 | H50: 54194 | I50: 0.01 | J50: 54194 | K50: 0.01
B51: Utilidad del Ejercicio | E51: 419359 | G51: 0.11 | H51: 531466 | I51: 0.1 | J51: 377879 | K51: 0.07
E52: 1925113 | G52: 0.5 | H52: 2456579 | I52: 0.44 | J52: 2834459 | K52: 0.52
B53: TOTAL DE CAPITAL CONTABLE | E53: 1925113 | G53: 0.5 | H53: 2456579 | I53: 0.44 | J53: 2834459 | K53: 0.52
B54: TOTAL DE PASIVO + CAPITAL | E54: 3901734 | G54: 1 | H54: 5571177 | I54: 1 | J54: 5464459 | K54: 1
...

Sheet resumen ejecutivo
B2: Banregio Grupo Financiero
B3: SOLICITANTE | F3: =#N/A -> #N/A
B5: ACTIVIDAD | D5: AÑOS EN SU ACTIVIDAD | F5: 40 AÑOS
D7: ACTIVIDAD / PRODUCTOS / MARCA | F7: FABRICACIÓN DE GALLETAS DULCES Y DERIVADOS DE LAS MARCA MARIAN. SUS PRINCIPALES PRODUCTOS SON LAS GALLETAS DE TIPO SURTIDO MARIAN CLASICO Y SURTIDO MARIAN TRADICIONAL.
D9: PRINCIPALES CLIENTES | F9: NUEVA WAL MART (22%), COSTCO DE MÉXICO (12%), TIENDAS SORIANA (11%)
B12: EXPERIENCIA CON BGF | D12: CLIENTE DE CREDITO DESDE | F12: =#N/A -> #N/A | H12: CALIFICACION DE CARTERA | I12: N.A. | J12: PRE CALIFICACION DE CARTERA | L12: =#N/A -> #N/A
D14: FUERZAS / OPORTUNIDADES | I14: DEBILIDADES / AMENAZAS
G17: ( UNIDADES ) | K17: (MILES DE PESOS)
G18: N° DE CONTRATOS ARRENDADOS | K18: RTAS X DEV. | L18: SALDO
G19: VIGENTES | H19: TERMINADOS | I19: TOTAL
E20: ($501- ) | G20: 0 | I20: =+G20+H20 -> 0 | K20: 0
E21: ($201 - $500) | G21: 0 | I21: =+G21+H21 -> 0 | K21: 0
E22: ($0 - $200) | G22: 1 | I22: =+G22+H22 -> 1 | K22: 137
D24: SINIESTRO | H24: 8 | I24: =+G24+H24 -> 8
D25: CANCELACIÓN ANTICIPADA | H25: 0 | I25: =+G25+H25 -> 0
D26: TRANSPASO/ CESIÓN | H26: 0 | I26: =+G26+H26 -> 0
D27: TERMINACIÓN NORMAL | H27: 174 | I27: =+G27+H27 -> 174
D28: SALDOS VENCIDOS | K28: 3
D30: TOTALES | G30: =SUM(G20:G29) -> 1 | H30: =SUM(H20:H29) -> 182 | I30: =SUM(I20:I29) -> 183 | K30: =SUM(K20:K29) -> 140
D31: % | G31: =+IF(I30=0,0,G30/I30) -> 0.0054644809 | H31: =+IF(J30=0,0,H30/J30) -> 0 | I31: =+IF(K30=0,0,I30/K30) -> 1.3071429
D33: RENTAS DEVENGADAS | G33: 25
D35: PAGO DE RENTA MENSUAL ACTUAL | G35: 3.5 | I35: INTERES MORATORIO COBRADO DESDE | L35: 0
I36: EL ORIGEN DE LA CUENTA | L36: =IF((K30+G33)=0,0,+L35/(K30+G33)) -> 0
D37: RENTA PROMEDIO X UNIDAD | G37: =IF(G30=0,0,G35/G30) -> 3.5
B40: COMP. DE PAGO EN BC | D40: FECHA DE CONSULTA DE BC | F40: =#N/A -> #N/A | G40: CALIFICACION BURO DE CRÉDITO | I40: 1 B1 , 1 A2
D44: INSTITUCIÓN | E44: TIPO DE CRÉDITO | F44: N° DE | G44: ULTIMO | H44: HIST. 12 MESES | I44: FECHA DE | J44: SALDO
F45: CRÉDITOS | G45: MOP | I45: ACTUALIZACIÓN | J45: ORIGINAL | K45: VIGENTE | L45: VENCIDO
D47: ARRENDAMIENTO PURO (MASTERLEASE) | F47: 1 | G47: 1 | H47: 1 | I47: DICIEMBRE 09 | J47: 113 | K47: 106 | L47: 0
D48: OTRAS FINANCIERAS (ARREND PURO) | F48: 4 | G48: 2 | H48: 4 | I48: DICIEMBRE 09 | J48: 768 | K48: 202 | L48: 3
D49: CRÉDITO FISCAL | F49: 3 | G49: 5 | H49: 5 | I49: DICIEMBRE 09 | J49: =0.8+0.8+2 -> 3.6 | K49: 0 | L49: =+J49 -> 3.6
D50: BANCO (DESCUENTOS) | F50: 1 | G50: 1 | H50: 1 | I50: ENERO 10 | J50: 4858 | K50: 4038 | L50: 0
D51: LINEAS DE CRÉDITO (OTRAS FINANCIERAS) | F51: 5 | G51: 1 | H51: 1 | I51: DICIEMBRE 09 | J51: =2+0.6+0.7+3+20 -> 26.3 | K51: 0
D52: BANCO (SIMPLE) | F52: 3 | G52: 2 | H52: 2 | I52: ENERO 10 | J52: =2000+2250+8500 -> 12750 | K52: =1680+1064+8500 -> 11244 | L52: 0
D53: BANCO (TARJETA DE SERVICIO) | F53: 4 | G53: 1 | H53: 3 | I53: DICIEMBRE 09 | J53: 0 | K53: =50+54+39 -> 143 | L53: 0
E56: TOTAL | F56: =SUM(F48:F55) -> 20 | J56: =SUM(J47:J55) -> 18518.9 | K56: =SUM(K47:K55) -> 15733 | L56: =SUM(L48:L55) -> 6.6
D60: Notas:
D61: EL IMPORTE VENCIDO QUE REPORTAN LAS OTRAS FINANCIERAS ES UN SALDO DE $ 3,
D62: LOS SALDOS CON EL SAT (CREDITOS FISCALES) PRESENTAN UNA CLAVE DE OBSERVACION PC = CUENTA EN COBRANZA
D66: FUERZAS / OPORTUNIDADES | I66: DEBILIDADES / AMENAZAS
D67: -LOS SALDOS VENCIDOS NO SON REPRESENTATIVOS DE LOS SALDOS VIGIENTES Y CONSIDERANDO LAS CALIFICACIONES DE BURÓ DE CRÉDITO DE B1 Y A2 SE CONSIDERA SU HISTORIAL EN BURÓ DE CRÉDITO COMO REGULAR.
...

Sheet RIESGO ACTUAL
B5: =#REF! -> #REF!
B7: =#N/A -> #N/A
L8: =#N/A -> #N/A
D10: CLIENTE DESDE | E10: =#N/A -> #N/A
C12: NEGOCIO / CONVENIENCIA | G12: =+B7 -> #N/A
G14: ( UNIDADES ) | K14: (MILES DE PESOS)
G15: N° DE CONTRATOS ARRENDADOS | K15: RIESGO ACTUAL
G16: VIGENTES | H16: TERMINADOS | I16: TOTAL
D17: EJECUTIVOS | E17: ($501- ) | G17: 0 | I17: =+G17+H17 -> 0 | K17: 0
D18: EMPLEADOS | E18: ($201 - $500) | G18: 0 | I18: =+G18+H18 -> 0 | K18: 0
D19: UTILITARIOS | E19: ($0 - $200) | G19: 48 | I19: =+G19+H19 -> 48 | K19: 3689
D21: SINIESTRO | H21: 11 | I21: =+G21+H21 -> 11
D22: CANCELACIÓN ANTICIPADA | H22: 4 | I22: =+G22+H22 -> 4
D23: TRANSPASO/ CESIÓN | H23: 27 | I23: =+G23+H23 -> 27
D24: TERMINACIÓN NORMAL | H24: 219 | I24: =+G24+H24 -> 219
D26: TOTALES | G26: =SUM(G17:G25) -> 48 | H26: =SUM(H17:H25) -> 261 | I26: =SUM(I17:I25) -> 309 | K26: =SUM(K17:K25) -> 3689
D27: % | G27: =+G26/I26 -> 0.15533981 | H27: =+H26/I26 -> 0.84466019 | I27: =+I26/I26 -> 1
D32: NUMERO DE UNIDADES ARRENDADAS ACTUALES
D34: EJECUTIVOS | E34: ($501- ) | G34: 0
D35: EMPLEADOS | E35: ($201 - $500) | G35: 22
D36: UTILITARIOS | E36: ($0 - $200) | G36: 90
D38: TOTAL | G38: =SUM(G34:G36) -> 112
D41: TOTAL DE CONTRATOS OPERADOS (HISTORICO Y ACTUAL) | G41: =+G38+G49 -> 200
D44: SINIESTRO | G44: 10
D45: CANCELACIÓN ANTICIPADA | G45: 0
D46: TRANSPASO/ CESIÓN | G46: 0
D47: TERMINACIÓN NORMAL | G47: 78
D49: TOTAL DE CONTRATOS TERMINADOS | G49: =SUM(G44:G48) -> 88
D50: % | G50: =+G49/G41 -> 0.44
D53: RIESGO A LA FECHA | J53: (MILES DE PESOS)
G54: RIESGO ACTUAL
D56: EJECUTIVOS | E56: ($501- ) | G56: 0
D57: EMPLEADOS | E57: ($201 - $500) | G57: 10128
D58: UTILITARIOS | E58: ($0 - $200) | G58: 6486
D61: TOTAL | G61: =SUM(G56:G58) -> 16614
D64: PAGO DE RENTA MENSUAL ACTUAL | G64: 159.6
D66: RENTA PROMEDIO X UNIDAD | G66: =+G64/G26 -> 3.325
I67: CALIFICACION DE CONVENIENCIA | J67: BUENA
C71: COMPORTAMIENTO DE PAGO | D71: EXPERIENCIA INTERNA DE MASTERLEASE
D72: INTERES MORATORIO COBRADO DESDE
...

Sheet TERRENOS
C9: =#N/A -> #N/A
C11: RELACIONES ANALÍTICAS
C13: =#REF! -> #REF!
C15: TERRENOS
C17: DESCRIPCIÓN | D17: UBICACIÓN | E17: SUP. MTS² | F17: VALOR DE ADQUISICIÓN | G17: REVALUACIÓN | H17: VALOR TOTAL
C19: TERRENO | D19: LOTE 21 Y 44 DE FRACC CD. INDUSTRIAL, CELAYA, GTO | E19: 2115.5 | F19: 846 | G19: 998.2 | H19: =+F19+G19 -> 1844.2
C21: TERRENO | D21: LOTE 32 Y 33 DE FRACC ARBOLEDAS, UNIDAD PARQUES RESIDENCIALES DE QUERETARO, QRO. | E21: 3900 | F21: 3962.7 | G21: 4644.2 | H21: =+F21+G21 -> 8606.9
C23: EDIFICIO | D23: LOTE 32 Y 33 DE FRACC ARBOLEDAS, UNIDAD PARQUES RESIDENCIALES DE QUERETARO, QRO. | F23: 7291 | G23: 6252.5 | H23: =+F23+G23 -> 13543.5
C25: TERRENO | D25: LOTE EN FRACC LA TABLA DE LA VIRGEN, LEON, GTO. | E25: 2004.9 | F25: 1816.5 | G25: 1679.9 | H25: =+F25+G25 -> 3496.4
C27: EDIFICIO | D27: LOTE EN FRACC LA TABLA DE LA VIRGEN, LEON, GTO. | F27: 2461.5 | G27: 212.5 | H27: =+F27+G27 -> 2674
C29: TERRENO | D29: LOTE EN MIGUEL ALEMAN KM 14.8 APODACA, N.L. | E29: 4918 | F29: 4864.7 | G29: 2188.8 | H29: =+F29+G29 -> 7053.5
C31: EDIFICIO | D31: LOTE EN MIGUEL ALEMAN KM 14.8 APODACA, N.L. | F31: 1372.5 | G31: 0 | H31: =+F31+G31 -> 1372.5
C33: TERRENO | D33: LOTE EN MANZANA 5, DISTRITO 1-81 FRACC CUAUTITLÁN IZCALLI | E33: 4927296 | F33: 2082 | G33: 2456.6 | H33: =+F33+G33 -> 4538.6
C35: EDIFICIO | D35: LOTE EN MANZANA 5, DISTRITO 1-81 FRACC CUAUTITLÁN IZCALLI | F35: 15526.7 | G35: 10406.7 | H35: =+F35+G35 -> 25933.4
C37: TERRENO | D37: LOTE EN MANZANA 12, NUMERO 319 DE CALLE 21, UBICADO EN MERIDA, CD. INDUSTRIAL | F37: 497.5 | G37: 54.725 | H37: =+F37+G37 -> 552.225
C39: EDIFICIO | D39: LOTE EN MANZANA 12, NUMERO 319 DE CALLE 21, UBICADO EN MERIDA, CD. INDUSTRIAL | F39: 3009.9 | G39: 121.9 | H39: =+F39+G39 -> 3131.8
C41: EDIFICIO | D41: CONSTRUCCIÓN EN TEPOZTLAN, EDO MÉXICO, SOBRE TERRENO PROPIEDAD DE BIENES DEL CENTRO | F41: 63524.88 | G41: 966 | H41: =+F41+G41 -> 64490.88
D45: TOTAL | F45: =SUM(F19:F41) -> 107255.88 | G45: =SUM(G19:G41) -> 29982.025 | H45: =SUM(H19:H41) -> 137237.9

Sheet ANEXO1
B5: =#REF! -> #REF!
B7: =#N/A -> #N/A
B8: ANEXO 1
C10: AVAL 1: | D10: RAMIRO GONZALEZ GONZALEZ
D11: RFC | F11: GOGR 741111 EN8
D12: ESTADO CIVIL | F12: SOLTERO
D13: EDAD | F13: 35 AÑOS
C15: BALANCE GENERAL
C16: AL 31 DE ENERO DEL 2009
D18: ACTIVO CIRCULANTE | H18: 0
D20: ACTIVO FIJO
E21: TERRENOS Y EDIFICIOS | G21: 42000
D23: TOTAL ACTIVO FIJO | H23: =G21 -> 42000
D25: TOTAL ACTIVO | H25: =+H23+H18 -> 42000
D27: PASIVO CIRCULANTE | H27: 0
D29: PASIVO LARGO PLAZO | H29: 0
D31: PASIVO TOTAL | H31: =H29+H27 -> 0
D33: PATRIMONIO | H33: =H25-H31 -> 42000
D35: ESTADO DE RESULTADOS
D37: NO DISPONIBLE
C39: INMUEBLES REPORTADOS
C40: DESCRIPCIÓN | E40: MTS² | F40: MTS² | G40: VALOR | H40: PROPIETARIO | I40: VERIF | J40: FECHA
E41: TERRENO | F41: COSNTR.
B42: 1.- | C42: TERRENO URBANO INDUSTRIAL, UBICADO EN LOTE N° 2 MANZANA N° 37, DISTRITO INDUSTRIAL MARITIMO DE ALTAMIRA, TAMPS. | E42: 42282 | F42: N.D. | G42: 39000 | H42: =D10 -> RAMIRO GONZALEZ GONZALEZ | I42: LIBRE DE GRAVAMEN | J42: 39987
C43: REG: 3803, VOL: 33, LIB 6-077, FECHA: 06-03-2003, TAMPS.
B44: 2.- | C44: DEPARTAMENTO UBICADO EN AVE. LOS ARCANGELES N° 1001, FRACC. LOS ARCANGELES, SAN PEDRO GRAZA GARCÍA, N.L. | E44: 230 | F44: N.D. | G44: 3000 | H44: =H42 -> RAMIRO GONZALEZ GONZALEZ | I44: LIBRE DE GRAVAMEN | J44: 39989
C45: REG: 860, VOL: 98, LIB 36, FECHA: 06-06-2006
C47: TOTAL | E47: =SUM(E42:E44) -> 42512 | G47: =SUM(G42:G44) -> 42000
D49: B.R. LIBRES | F49: 2 | G49: 42000
D50: B.R. GRAVADOS
D51: B.R. TERCEROS
D52: B.R. PENDIENTES
D54: TOTAL BIENES RAICES | F54: =SUM(F49:F53) -> 2 | G54: =SUM(G49:G52) -> 42000
C55: BURÓ DE CRÉDITO
C57: FECHA DE CONSULTA | E57: 40049 | G57: CANTIDAD DE CUENTAS ABIERTAS | J57: 6
C58: SALDO VIGENTE | E58: 342 | G58: CANTIDAD DE CUENTAS CERRADAS | J58: 4
C59: SALDO VENCIDO | E59: 0 | G59: NUMERO DE CONSULTAS | J59: 36
C60: MOP MAXIMO ULTIMO AÑO | E60: 1
C62: CALIFICACIÓN BURÓ | E62: 1A1 | G62: INTERPRETACIÓN | I62: BUEN HISTORIAL
C63: BC SCORE | E63: 701
...

Sheet CALIF
A2: =#REF! -> #REF! | U2: Sectores de Actividad Económica | Z2: Calificación de Riesgo Trim I 2009
U3: Agropecuario, Silvicultura y Pesca | Z3: B-3
A4: RAZONES FINANCIERAS HISTÓRICAS PARA CALIFICACIÓN DE LA CARTERA | U4: Minería | Z4: D
F5: =#REF! -> #REF! | H5: =#REF! -> #REF! | J5: =#REF! -> #REF! | U5: Electricidad, Gas y Agua | Z5: C-1
A6: FLUJO DE EFECTIVO | U6: Construcción | Z6: C-1
A7: Flujo Operativo / Total Financiamiento Externo | D7: Base | F7: 0 | H7: =#REF!/(#REF!+#REF!) -> #REF! | J7: =#REF!/(#REF!+#REF!) -> #REF! | U7: Industria Manufacturera | Z7: C-1
A8: Flujo Operativo / Pasivo Corto Plazo | D8: Base | F8: 0 | H8: =#REF!/#REF! -> #REF! | J8: =#REF!/#REF! -> #REF! | U8: Carnes y Lácteos | Z8: B-3
A9: Flujo Operativo / Pasivo Total | D9: Base | F9: 0 | H9: =#REF!/#REF! -> #REF! | J9: =#REF!/#REF! -> #REF! | U9: Textiles, Prendas de Vestir e Industria del Cuero | Z9: D
A10: EBITDA / Intereses | D10: Base | F10: =#REF! -> #REF! | H10: =#REF! -> #REF! | J10: =#REF! -> #REF! | M10: Actividad o giro | N10: =#N/A -> #N/A | U10: Imprentas y Editoriales | Z10: C-2
A11: EBITDA / Pasivo con Costo Financiero | D11: Base | F11: =#REF! -> #REF! | H11: =#REF! -> #REF! | J11: =#REF! -> #REF! | N11: B-3 | U11: Artículos de Plástico | Z11: C-1
U12: Productos a base de minerales no metálicos | Z12: C-1
A13: LIQUIDEZ | U13: Vidrio y Productos de Vidrio | Z13: B-3
A14: Indice de Liquidez | D14: 0 | F14: =#REF! -> #REF! | H14: =#REF! -> #REF! | J14: =#REF! -> #REF! | U14: Industrias Básicas de Hierro y Acero | Z14: C-1
A15: Liquidez Inmediata | D15: 0 | F15: =#REF! -> #REF! | H15: =#REF! -> #REF! | J15: =#REF! -> #REF! | U15: Productos Metálicos, Maquinaria y Equipo | Z15: C-1
A16: Capital de Trabajo Neto ($) | D16: 0 | F16: =#REF! -> #REF! | H16: =#REF! -> #REF! | J16: =#REF! -> #REF! | U16: Comercio, Restaurantes y Hoteles | Z16: C-1
U17: Comercio | Z17: C-1
A18: APALANCAMIENTO | U18: Transporte, Almacenaje y Comunicaciones | Z18: B-3
A19: Pasivo Total / Activo Total | D19: 0 | F19: =#REF! -> #REF! | H19: =#REF! -> #REF! | J19: =#REF! -> #REF! | U19: Transporte | Z19: C-1
A20: Pasivo Total / Capital Contable | D20: 0 | F20: =#REF! -> #REF! | H20: =#REF! -> #REF! | J20: =#REF! -> #REF! | U20: Servicios Financieros, Seguros, Actividades Inmobiliarias y de Alquiler | Z20: C-1
A21: Instituciones Financieras / Pasivo Total | D21: 0 | F21: =#REF! -> #REF! | H21: =#REF! -> #REF! | J21: =#REF! -> #REF! | U21: Servicios Comunales, Sociales y Personales | Z21: C-1
U22: Servicios Profesionales | Z22: C-2
A23: RENTABILIDAD Y EFICIENCIA | U23: Servicios Médicos | Z23: B-3
A24: Utilidad Neta / Activo Total | D24: 0 | F24: =#REF! -> #REF! | H24: =#REF! -> #REF! | J24: =#REF! -> #REF! | U24: Agrupaciones mercantiles, profesionales, cívicas, políticas, laborales y religiosas | Z24: B-3
A25: Utilidad Neta / Capital Contable | D25: 0 | F25: =#REF! -> #REF! | H25: =#REF! -> #REF! | J25: =#REF! -> #REF! | U25: Gobierno | Z25: B-3
A26: Utilidad Neta / Ventas Netas | D26: 0 | F26: =#REF! -> #REF! | H26: =#REF! -> #REF! | J26: =#REF! -> #REF! | U26: Empleados, profesionistas independientes y similares | Z26: C-2
A27: Utilidad Oper. / Ints. Pagados | D27: 0 | F27: =IF(#REF!=0,0,#REF!/#REF!) -> #REF! | H27: =IF(#REF!=0,0,#REF!/#REF!) -> #REF! | J27: =IF(#REF!=0,0,#REF!/#REF!) -> #REF!
A28: Días Cartera | D28: 0 | F28: =#REF! -> #REF! | H28: =#REF! -> #REF! | J28: =#REF! -> #REF!
A29: Días Inventarios | D29: 0 | F29: =#REF! -> #REF! | H29: =#REF! -> #REF! | J29: =#REF! -> #REF!
A30: Ciclo Financiero | D30: 0 | F30: =F28+F29 -> #REF! | H30: =H28+H29 -> #REF! | J30: =J28+J29 -> #REF!
A31: Días Proveedores | D31: 0 | F31: =#REF! -> #REF! | H31: =#REF! -> #REF! | J31: =#REF! -> #REF!
B32: C A L I F I C A C I O N E S | E32: Calificación | F32: Calificación | G32: Calificación | H32: Reservas
B33: Riesgo | C33: Riesgo | D33: Riesgo | E33: Experiencia | F33: Acumulada | G33: A1 = 1 | H33: 0.005
B34: País | C34: Financiero | D34: Industria | E34: de Pago B.C. | F34: del Deudor | G34: A2 = 2 | H34: 0.0099
B35: 0 | C35: =K80 -> #REF! | D35: =VLOOKUP(D36,$O$41:$P$49,2) -> 5 | E35: =VLOOKUP(E36,$O$41:$P$49,2) -> 7 | F35: =HLOOKUP(E35,C49:K58,C35+1) -> #REF! | G35: B1 = 3 | H35: 0.0499
C36: =VLOOKUP(C35,$P$85:$Q$93,2) -> #REF! | D36: B3 | E36: =VLOOKUP(Pre_calif!K46,M41:O49,3) -> C2 | F36: =VLOOKUP(F35,$P$85:$Q$93,2) -> #REF! | G36: B2 = 4 | H36: 0.0999
F37: =(VLOOKUP(F35,$P$85:$R$93,3)) -> #REF! | G37: B3 = 5 | H37: 0.1999
G38: C1 = 6 | H38: 0.3999
G39: C2 = 7 | H39: 0.5999
G40: D = 8 | H40: 0.8999
G41: E = 9 | H41: 1 | M41: 0 | N41: 0 | O41: A1 | P41: 1
...

Sheet Pre_calif
D10: Pre – Calificación del Deudor
E13: Nombre del Cliente: | G13: =+#REF! -> #REF!
E14: Fecha de la Pre Calificación | G14: =#N/A -> #N/A
E15: Analista | G15: =#N/A -> #N/A
E17: Calificación del Deudor | G17: =L27 -> #REF!
E19: Sector | G19: =+sectores!L13 -> INDUSTRIA MANUFACTURERA
E20: Giro | G20: =+CALIF!N10 -> #N/A
D24: Riesgo | E24: Riesgo | I24: Riesgo | J24: Experiencia | L24: Calificación
D25: País | E25: Financiero | I25: Industria | J25: de Pago B.C. | L25: del Deudor
D27: N.A. | E27: =CALIF!C36 -> #REF! | I27: =VLOOKUP(G19,sectores!L7:M17,2) -> C1 | J27: =CALIF!E36 -> C2 | L27: =CALIF!F36 -> #REF!
E33: Pond. | F33: Razones Financieras | J33: Solicitante
J34: Fecha Buró | K34: =#N/A -> #N/A
E35: =CALIF!O68 -> 0.2 | F35: Cobertura de Intereses: | G35: =CALIF!J68 -> #REF! | H35: =CALIF!K68*CALIF!O68 -> #REF! | J35: Días de atraso buró | K35: 120
E36: =CALIF!O69 -> 0.2 | F36: Cob.Ints.Respecto a Flujo Fondos: | G36: =CALIF!J69 -> #REF! | H36: =CALIF!K69*CALIF!O69 -> #REF! | J36: Días de atraso Banregio | K36: 0
E37: =CALIF!O70 -> 0.1333 | F37: Cobertura de la Deuda: | G37: =CALIF!J70 -> #REF! | H37: =CALIF!K70*CALIF!O70 -> #REF! | J37: Días de atraso AF Banregio | K37: 0
E38: =CALIF!O71 -> 0.1333 | F38: Cobertura neta de la Deuda: | G38: =CALIF!J71 -> #REF! | H38: =CALIF!K71*CALIF!O71 -> #REF!
E39: =CALIF!O72 -> 0.0667 | F39: Rendimiento del Capital: | G39: =CALIF!J72 -> #REF! | H39: =CALIF!K72*CALIF!O72 -> #REF! | J39: Aval
E40: =CALIF!O73 -> 0.0667 | F40: Margen de Operación: | G40: =CALIF!J73 -> #REF! | H40: =CALIF!K73*CALIF!O73 -> #REF! | J40: Fecha Buró | K40: 0
E41: =CALIF!O77 -> 0.0667 | F41: Pas.c/Costo Fin. LP a Cap. Cont.: | G41: =CALIF!J77 -> #REF! | H41: =CALIF!K77*CALIF!O77 -> #REF! | J41: Días de atraso buró | K41: 0
E42: =CALIF!O78 -> 0.1333 | F42: Pas.c/Costo Fin.Total a Cap. Cont.: | G42: =CALIF!J78 -> #REF! | H42: =CALIF!K78*CALIF!O78 -> #REF! | J42: Días de atraso Banregio | K42: 0
J43: Días de atraso AF Banregio | K43: 0
E44: =SUM(E32:E43) -> 1 | F44: Resultado | H44: =SUM(H32:H43) -> #REF!
F46: A1 | G46: 1 a 4.99 | J46: Mayor atraso | K46: =MAX(K35,K36,K37,K41,K42,K43) -> 120
F47: A2 | G47: 5 a 5.99
F48: B1 | G48: 6 a 6.33
F49: B2 | G49: 6.34 a 6.66
F50: B3 | G50: 6.67 a 6.99
F51: C1 | G51: 7 a 7.99
F52: C2 | G52: 8 a 8.99
F53: D | G53: 9
F54: E | G54: 9

Sheet sectores
D1: ACTIVIDAD DE CATALOGO | E1: SECTOR | F1: SUBSECTOR | G1: RAMA | H1: ACTIVIDAD ESPECÍFICA
D2: ACABADO DE HILOS | E2: INDUSTRIA MANUFACTURERA | F2: TEXTILES, PRENDAS DE VESTIR E INDUSTRIA DEL CUERO | G2: HILADO Y TEJIDO DE FIBRAS BLANDAS | H2: 220-ACABADO DE HILOS
D3: ACABADO DE TELAS | E3: INDUSTRIA MANUFACTURERA | F3: TEXTILES, PRENDAS DE VESTIR E INDUSTRIA DEL CUERO | G3: HILADO Y TEJIDO DE FIBRAS BLANDAS | H3: 228-ACABADO DE TELAS
D4: ACTIVIDADES DE CLUBES DEPORTIVOS PROFESIONALES | E4: SERVICIOS COMUNALES, SOCIALES Y PERSONALES | F4: SERVICIOS PROFESIONALES, DE EDUCACIÓN, MÉDICOS Y DE ESPARCIMIENTO | G4: SERVICIOS DE ESPARCIMIENTO | H4: 935-ACTIVIDADES DE CLUBES DEPORTIVOS PROFESIONALES
D5: ADMINISTRACION DE CAMINOS PUENTES Y SERVICIOS AUXILIARES | E5: TRANSPORTE, ALMACENAMIENTO Y COMUNICACIONES | F5: TRANSPORTE Y ALMACENAMIENTO | G5: TRANSPORTE | H5: 830-ADMINISTRACION DE CAMINOS PUENTES Y SERVICIOS AUXILIARES | L5: Calificación de Riesgo Primer Trimestre del 2009
D6: ADMINISTRACION DE CAMINOS PUENTES Y SERVICIOS AUXILIARES (GOBIERNO) | E6: GOBIERNO, AGRUPACIONES Y ORGANIZACIONES INTERNACIONALES | F6: GOBIERNO | G6: OTROS SERVICIOS Y ACTIVIDADES DE ADMINISTRACION PUBLICA | H6: 1035-ADMINISTRACION DE CAMINOS PUENTES Y SERVICIOS AUXILIARES (GOBIERNO)
D7: ADMINISTRACION DE CENTRALES CAMIONERAS Y SERVICIOS AUXILIARES | E7: TRANSPORTE, ALMACENAMIENTO Y COMUNICACIONES | F7: TRANSPORTE Y ALMACENAMIENTO | G7: TRANSPORTE | H7: 833-ADMINISTRACION DE CENTRALES CAMIONERAS Y SERVICIOS AUXILIARES | K7: 1 | L7: AGROPECUARIO,SILVICULTURA, CAZA Y PESCA | M7: B3
D8: ADMINISTRACION DE CENTRALES CAMIONERAS Y SERVICIOS AUXILIARES (GOBIERNO) | E8: GOBIERNO, AGRUPACIONES Y ORGANIZACIONES INTERNACIONALES | F8: GOBIERNO | G8: OTROS SERVICIOS Y ACTIVIDADES DE ADMINISTRACION PUBLICA | H8: 1038-ADMINISTRACION DE CENTRALES CAMIONERAS Y SERVICIOS AUXILIARES (GOBIERNO) | K8: 2 | L8: COMERCIO, RESTAURANTES Y HOTELES | M8: C1
D9: ADMINISTRACION DE INMUEBLES | E9: SERVICIOS FINANCIEROS, SEGUROS Y BIENES INMUEBLES | F9: BIENES INMUEBLES | G9: ALQUILER DE INMUEBLES | H9: 885-ADMINISTRACION DE INMUEBLES | K9: 3 | L9: CONSTRUCCION | M9: C1
D10: ADMINISTRACION DE PUERTOS MARITIMOS LACUSTRES Y FLUVIALES | E10: TRANSPORTE, ALMACENAMIENTO Y COMUNICACIONES | F10: TRANSPORTE Y ALMACENAMIENTO | G10: TRANSPORTE | H10: 832-ADMINISTRACION DE PUERTOS MARITIMOS LACUSTRES Y FLUVIALES | K10: 4 | L10: ELECTRICIDAD, GAS Y AGUA | M10: C1
D11: ADMINISTRACION DE PUERTOS MARITIMOS LACUSTRES Y FLUVIALES (GOBIERNO) | E11: GOBIERNO, AGRUPACIONES Y ORGANIZACIONES INTERNACIONALES | F11: GOBIERNO | G11: OTROS SERVICIOS Y ACTIVIDADES DE ADMINISTRACION PUBLICA | H11: 1037-ADMINISTRACION DE PUERTOS MARITIMOS LACUSTRES Y FLUVIALES (GOBIERNO) | K11: 5 | L11: EMPLEADOS, PROFESIONISTAS INDEPENDIENTES Y SIMILARES | M11: B3
D12: AEROPUERTO CIVIL | E12: TRANSPORTE, ALMACENAMIENTO Y COMUNICACIONES | F12: TRANSPORTE Y ALMACENAMIENTO | G12: TRANSPORTE | H12: 831-AEROPUERTO CIVIL | K12: 6 | L12: GOBIERNO, AGRUPACIONES Y ORGANIZACIONES INTERNACIONALES | M12: B3
D13: AEROPUERTO CIVIL (GOBIERNO) | E13: GOBIERNO, AGRUPACIONES Y ORGANIZACIONES INTERNACIONALES | F13: GOBIERNO | G13: OTROS SERVICIOS Y ACTIVIDADES DE ADMINISTRACION PUBLICA | H13: 1036-AEROPUERTO CIVIL (GOBIERNO) | K13: 7 | L13: INDUSTRIA MANUFACTURERA | M13: C1
D14: AGENCIA ADUANAL | E14: TRANSPORTE, ALMACENAMIENTO Y COMUNICACIONES | F14: TRANSPORTE Y ALMACENAMIENTO | G14: TRANSPORTE | H14: 836-AGENCIA ADUANAL | K14: 8 | L14: MINERÍA | M14: D
D15: AGENCIA ADUANAL (GOBIERNO) | E15: GOBIERNO, AGRUPACIONES Y ORGANIZACIONES INTERNACIONALES | F15: GOBIERNO | G15: OTROS SERVICIOS Y ACTIVIDADES DE ADMINISTRACION PUBLICA | H15: 1041-AGENCIA ADUANAL (GOBIERNO) | K15: 9 | L15: SERVICIOS COMUNALES, SOCIALES Y PERSONALES | M15: C1
D16: AGENCIA DE FERROCARRIL | E16: TRANSPORTE, ALMACENAMIENTO Y COMUNICACIONES | F16: TRANSPORTE Y ALMACENAMIENTO | G16: TRANSPORTE | H16: 838-AGENCIA DE FERROCARRIL | K16: 10 | L16: SERVICIOS FINANCIEROS, SEGUROS Y BIENES INMUEBLES | M16: C1
D17: AGENCIA DE FERROCARRIL (GOBIERNO) | E17: GOBIERNO, AGRUPACIONES Y ORGANIZACIONES INTERNACIONALES | F17: GOBIERNO | G17: OTROS SERVICIOS Y ACTIVIDADES DE ADMINISTRACION PUBLICA | H17: 1043-AGENCIA DE FERROCARRIL (GOBIERNO) | K17: 11 | L17: TRANSPORTE, ALMACENAMIENTO Y COMUNICACIONES | M17: B3
D18: AGENCIA DE INHUMACIONES | E18: SERVICIOS COMUNALES, SOCIALES Y PERSONALES | F18: OTROS SERVICIOS | G18: OTROS SERVICIOS | H18: 980-AGENCIA DE INHUMACIONES
D19: AGENCIA DE MUDANZAS | E19: TRANSPORTE, ALMACENAMIENTO Y COMUNICACIONES | F19: TRANSPORTE Y ALMACENAMIENTO | G19: TRANSPORTE | H19: 817-AGENCIA DE MUDANZAS
D20: AGENCIA DE MUDANZAS (GOBIERNO) | E20: GOBIERNO, AGRUPACIONES Y ORGANIZACIONES INTERNACIONALES | F20: GOBIERNO | G20: OTROS SERVICIOS Y ACTIVIDADES DE ADMINISTRACION PUBLICA | H20: 1022-AGENCIA DE MUDANZAS (GOBIERNO)
D21: AGENCIA DE PUBLICIDAD | E21: SERVICIOS COMUNALES, SOCIALES Y PERSONALES | F21: SERVICIOS PROFESIONALES, DE EDUCACIÓN, MÉDICOS Y DE ESPARCIMIENTO | G21: SERVICIOS PROFESIONALES | H21: 893-AGENCIA DE PUBLICIDAD
D22: AGENCIA DE TURISMO | E22: TRANSPORTE, ALMACENAMIENTO Y COMUNICACIONES | F22: TRANSPORTE Y ALMACENAMIENTO | G22: TRANSPORTE | H22: 835-AGENCIA DE TURISMO
D23: AGENCIA DE TURISMO (GOBIERNO) | E23: GOBIERNO, AGRUPACIONES Y ORGANIZACIONES INTERNACIONALES | F23: GOBIERNO | G23: OTROS SERVICIOS Y ACTIVIDADES DE ADMINISTRACION PUBLICA | H23: 1040-AGENCIA DE TURISMO (GOBIERNO)
D24: AGENCIA DE VAPORES Y BUQUES | E24: TRANSPORTE, ALMACENAMIENTO Y COMUNICACIONES | F24: TRANSPORTE Y ALMACENAMIENTO | G24: TRANSPORTE | H24: 824-AGENCIA DE VAPORES Y BUQUES
D25: AGENCIA DE VAPORES Y BUQUES (GOBIERNO) | E25: GOBIERNO, AGRUPACIONES Y ORGANIZACIONES INTERNACIONALES | F25: GOBIERNO | G25: OTROS SERVICIOS Y ACTIVIDADES DE ADMINISTRACION PUBLICA | H25: 1029-AGENCIA DE VAPORES Y BUQUES (GOBIERNO)
D26: AGENCIA NOTICIOSA | E26: SERVICIOS COMUNALES, SOCIALES Y PERSONALES | F26: SERVICIOS PROFESIONALES, DE EDUCACIÓN, MÉDICOS Y DE ESPARCIMIENTO | G26: SERVICIOS PROFESIONALES | H26: 894-AGENCIA NOTICIOSA
D27: AGENCIAS DE RIFAS Y SORTEOS (QUINIELAS Y LOTERIA) | E27: COMERCIO, RESTAURANTES Y HOTELES | F27: ARTICULOS DIVERSOS | G27: COMERCIO | H27: 789-AGENCIAS DE RIFAS Y SORTEOS (QUINIELAS Y LOTERIA)
D28: AGENTE DE BOLSA | E28: SERVICIOS FINANCIEROS, SEGUROS Y BIENES INMUEBLES | F28: SERVICIOS FINANCIEROS Y SEGUROS | G28: SERVICIOS FINANCIEROS | H28: 856-AGENTE DE BOLSA
D29: AGENTE DE BOLSA (GOBIERNO) | E29: SERVICIOS FINANCIEROS, SEGUROS Y BIENES INMUEBLES | F29: SERVICIOS FINANCIEROS Y SEGUROS | G29: SERVICIOS FINANCIEROS | H29: 874-AGENTE DE BOLSA (GOBIERNO)
... D1069: VULCANIZACION DE LLANTAS Y CAMARAS | E1069: INDUSTRIA MANUFACTURERA | F1069: SUSTANCIAS QUIMICAS, DERIVADOS DEL PETROLEO, CAUCHO Y PLASTICOS | G1069: PRODUCTOS DE HULE | H1069: 391-VULCANIZACION DE LLANTAS Y CAMARAS

Sheet Hoja10

Sheet Base
A1: =IF(#REF!="","",#REF!) -> #REF! | B1: =IF(#REF!="","",#REF!) -> #REF! | C1: =IF(#REF!="","",#REF!) -> #REF! | D1: =IF(#REF!="","",#REF!) -> #REF! | E1: =IF(#REF!="","",#REF!) -> #REF! | F1: =IF(#REF!="","",#REF!) -> #REF! | G1: =IF(#REF!="","",#REF!) -> #REF! | H1: =IF(#REF!="","",#REF!) -> #REF! | ... S1: =IF(#REF!="","",#REF!) -> #REF!
A2: =IF(#REF!="","",#REF!) -> #REF! | B2: =IF(#REF!="","",#REF!) -> #REF! | C2: =IF(#REF!="","",#REF!) -> #REF! | D2: =IF(#REF!="","",#REF!) -> #REF! | E2: =IF(#REF!="","",#REF!) -> #REF! | F2: =IF(#REF!="","",#REF!) -> #REF! | G2: =IF(#REF!="","",#REF!) -> #REF! | H2: =IF(#REF!="","",#REF!) -> #REF! | ... S2: =IF(#REF!="","",#REF!) -> #REF!
A3: =IF(#REF!="","",#REF!) -> #REF! | B3: =IF(#REF!="","",#REF!) -> #REF! | C3: =IF(#REF!="","",#REF!) -> #REF! | D3: =IF(#REF!="","",#REF!) -> #REF! | E3: =IF(#REF!="","",#REF!) -> #REF! | F3: =IF(#REF!="","",#REF!) -> #REF! | G3: =IF(#REF!="","",#REF!) -> #REF! | H3: =IF(#REF!="","",#REF!) -> #REF! | ... S3: =IF(#REF!="","",#REF!) -> #REF!
A4: =IF(#REF!="","",#REF!) -> #REF! | B4: =IF(#REF!="","",#REF!) -> #REF! | C4: =IF(#REF!="","",#REF!) -> #REF! | D4: =IF(#REF!="","",#REF!) -> #REF! | E4: =IF(#REF!="","",#REF!) -> #REF! | F4: =IF(#REF!="","",#REF!) -> #REF! | G4: =IF(#REF!="","",#REF!) -> #REF! | H4: =IF(#REF!="","",#REF!) -> #REF! | ... S4: =IF(#REF!="","",#REF!) -> #REF!
A5: =IF(#REF!="","",#REF!) -> #REF! | B5: =IF(#REF!="","",#REF!) -> #REF! | C5: =IF(#REF!="","",#REF!) -> #REF! | D5: =IF(#REF!="","",#REF!) -> #REF! | E5: =IF(#REF!="","",#REF!) -> #REF! | F5: =IF(#REF!="","",#REF!) -> #REF! | G5: =IF(#REF!="","",#REF!) -> #REF! | H5: =IF(#REF!="","",#REF!) -> #REF! | ... S5: =IF(#REF!="","",#REF!) -> #REF!
A6: =IF(#REF!="","",#REF!) -> #REF! | B6: =IF(#REF!="","",#REF!) -> #REF! | C6: =IF(#REF!="","",#REF!) -> #REF! | D6: =IF(#REF!="","",#REF!) -> #REF! | E6: =IF(#REF!="","",#REF!) -> #REF! | F6: =IF(#REF!="","",#REF!) -> #REF! | G6: =IF(#REF!="","",#REF!) -> #REF! | H6: =IF(#REF!="","",#REF!) -> #REF! | ... S6: =IF(#REF!="","",#REF!) -> #REF!
A7: =IF(#REF!="","",#REF!) -> #REF! | B7: =IF(#REF!="","",#REF!) -> #REF! | C7: =IF(#REF!="","",#REF!) -> #REF! | D7: =IF(#REF!="","",#REF!) -> #REF! | E7: =IF(#REF!="","",#REF!) -> #REF! | F7: =IF(#REF!="","",#REF!) -> #REF! | G7: =IF(#REF!="","",#REF!) -> #REF! | H7: =IF(#REF!="","",#REF!) -> #REF! | ... S7: =IF(#REF!="","",#REF!) -> #REF!
A8: =IF(#REF!="","",#REF!) -> #REF! | B8: =IF(#REF!="","",#REF!) -> #REF! | C8: =IF(#REF!="","",#REF!) -> #REF! | D8: =IF(#REF!="","",#REF!) -> #REF! | E8: =IF(#REF!="","",#REF!) -> #REF! | F8: =IF(#REF!="","",#REF!) -> #REF! | G8: =IF(#REF!="","",#REF!) -> #REF! | H8: =IF(#REF!="","",#REF!) -> #REF! | ... S8: =IF(#REF!="","",#REF!) -> #REF!
A9: =IF(#REF!="","",#REF!) -> #REF! | B9: =IF(#REF!="","",#REF!) -> #REF! | C9: =IF(#REF!="","",#REF!) -> #REF! | D9: =IF(#REF!="","",#REF!) -> #REF! | E9: =IF(#REF!="","",#REF!) -> #REF! | F9: =IF(#REF!="","",#REF!) -> #REF! | G9: =IF(#REF!="","",#REF!) -> #REF! | H9: =IF(#REF!="","",#REF!) -> #REF! | ... S9: =IF(#REF!="","",#REF!) -> #REF!
A10: =IF(#REF!="","",#REF!) -> #REF! | B10: =IF(#REF!="","",#REF!) -> #REF! | C10: =IF(#REF!="","",#REF!) -> #REF! | D10: =IF(#REF!="","",#REF!) -> #REF! | E10: =IF(#REF!="","",#REF!) -> #REF! | F10: =IF(#REF!="","",#REF!) -> #REF! | G10: =IF(#REF!="","",#REF!) -> #REF! | H10: =IF(#REF!="","",#REF!) -> #REF! | ... S10: =IF(#REF!="","",#REF!) -> #REF!
A11: =IF(#REF!="","",#REF!) -> #REF! | B11: =IF(#REF!="","",#REF!) -> #REF! | C11: =IF(#REF!="","",#REF!) -> #REF! | D11: =IF(#REF!="","",#REF!) -> #REF! | E11: =IF(#REF!="","",#REF!) -> #REF! | F11: =IF(#REF!="","",#REF!) -> #REF! | G11: =IF(#REF!="","",#REF!) -> #REF! | H11: =IF(#REF!="","",#REF!) -> #REF! | ... S11: =IF(#REF!="","",#REF!) -> #REF!
A12: =IF(#REF!="","",#REF!) -> #REF! | B12: =IF(#REF!="","",#REF!) -> #REF! | C12: =IF(#REF!="","",#REF!) -> #REF! | D12: =IF(#REF!="","",#REF!) -> #REF! | E12: =IF(#REF!="","",#REF!) -> #REF! | F12: =IF(#REF!="","",#REF!) -> #REF! | G12: =IF(#REF!="","",#REF!) -> #REF! | H12: =IF(#REF!="","",#REF!) -> #REF! | ... S12: =IF(#REF!="","",#REF!) -> #REF!
... A172: =IF(#REF!="","",#REF!) -> #REF! | B172: =IF(#REF!="","",#REF!) -> #REF! | C172: =IF(#REF!="","",#REF!) -> #REF! | D172: =IF(#REF!="","",#REF!) -> #REF! | E172: =IF(#REF!="","",#REF!) -> #REF! | F172: =IF(#REF!="","",#REF!) -> #REF! | G172: =IF(#REF!="","",#REF!) -> #REF! | H172: =IF(#REF!="","",#REF!) -> #REF! | ... S172: =IF(#REF!="","",#REF!) -> #REF!

Sheet Bal2
S3: Caja y Bancos | T3: Cuentas por Cobrar | U3: IVA por Acreditar | V3: Deudores Diversos | W3: Inventarios | X3: Reclamaciones por Garantia | Y3: Cuentas por Cobrar Filiales | Z3: Otros Activos Circulantes | AF3: Terrenos y Edificios | AG3: Maquinaria y Equipo | AH3: Muebles y Enseres | AI3: Equipo de Transporte | AJ3: Depreciacion Acumulada | AK3: Revaluacion de Activos | AL3: Mejoras al Local Arrendado | AR3: Pagos Anticipados | AS3: Cargos Diferidos | AT3: Inversiones en Valores | AU3: Credito al Salario | BC3: Proveedores | BD3: Creditos a Corto Plazo | BE3: Arrendadora a Corto Plazo | BF3: Impuestos a Pagar | BG3: Acreedores Diversos | BH3: Documentos por Pagar | BI3: Cuentas por Pagar Filiales | BJ3: Anticipos de Clientes | BK3: Porcion Circ. Deuda L.P. | BQ3: Creditos a Largo Plazo | BR3: Arrendadora a Largo Plazo | BS3: Documentos x Pagar a Largo Pla | BY3: Creditos Diferidos | BZ3: Estimacion Prima de Antiguedad | CH3: Capital Social | CI3: Reservas | CJ3: Aportaciones Futuros Aument | CK3: Actualizacion de Capital | CL3: Superavit por Reevaluacion | CM3: Utilidad Acumulada | CN3: Utilidad del Ejercicio | CO3: Otras Partidas | CP3: Patrimonio | DJ3: Ventas | DK3: Costo de Ventas | DL3: Sueldos | DM3: Ingresos Varios | DQ3: Gastos de Administracion | DR3: Gastos de Venta | DS3: Gastos Familiares | DY3: Productos Financieros (-) | DZ3: Gastos Financieros | EA3: Fluctuacion Cambiaria | EB3: REPOMO | EE3: Otros Ingresos (-) | EF3: Otras Partidas | EG3: Particip. en Result. de Subsid | EH3: Partidas Extraordinarias | EI3: Pago Creditos | EJ3: Gastos Varios | EN3: Impuestos
S4: 1 | T4: 2 | U4: 3 | V4: 4 | W4: 5 | X4: 6 | Y4: 7 | Z4: 8 | AF4: 9 | AG4: 10 | AH4: 11 | AI4: 12 | AJ4: 13 | AK4: 14 | AL4: 15 | AR4: 16 | AS4: 17 | AT4: 18 | AU4: 19 | BC4: 20 | BD4: 21 | BE4: 22 | BF4: 23 | BG4: 24 | BH4: 25 | BI4: 26 | BJ4: 27 | BK4: 28 | BL4: 29 | BQ4: 29 | BR4: 30 | BS4: 31 | BY4: 32 | BZ4: 33 | CH4: 34 | CI4: 35 | CJ4: 36 | CK4: 37 | CL4: 38 | CM4: 39 | CN4: 40 | CO4: 41 | CP4: 42 | DJ4: 43 | DK4: 44 | DL4: 45 | DM4: 46 | DQ4: 47 | DR4: 48 | DS4: 49 | DY4: 50 | DZ4: 51 | EA4: 52 | EB4: 53 | EE4: 54 | EF4: 55 | EG4: 56 | EH4: 57 | EI4: 58 | EJ4: 59 | EN4: 60
E6: =Bal!B6 -> 0 | F6: =Bal!C6 -> 0 | G6: =Bal!D6 -> 0 | H6: =Bal!E6 -> 2007 | I6: =Bal!F6 -> % | J6: =Bal!G6 -> 2008 | K6: =Bal!H6 -> % | L6: =Bal!I6 -> Jun - | ... N6: =Bal!K6 -> %
E7: =Bal!B7 -> 0 | F7: =Bal!C7 -> 0 | G7: =Bal!D7 -> 0 | H7: =Bal!E7 -> 0 | I7: =Bal!F7 -> 0 | J7: =Bal!G7 -> 0 | K7: =Bal!H7 -> 0 | L7: =Bal!I7 -> 0 | ... N7: =Bal!K7 -> 0
E8: =Bal!B8 -> BALANCE GENERAL | F8: =Bal!C8 -> 0 | G8: =Bal!D8 -> 0 | H8: =Bal!E8 -> 0 | I8: =Bal!F8 -> 0 | J8: =Bal!G8 -> 0 | K8: =Bal!H8 -> 0 | L8: =Bal!I8 -> 0 | ... N8: =Bal!K8 -> 0
E9: =Bal!B9 -> ACTIVO CIRCULANTE | F9: =Bal!C9 -> 0 | G9: =Bal!D9 -> 0 | H9: =Bal!E9 -> 0 | I9: =Bal!F9 -> 0 | J9: =Bal!G9 -> 0 | K9: =Bal!H9 -> 0 | L9: =Bal!I9 -> 0 | ... N9: =Bal!K9 -> 0
E10: =Bal!B10 -> 0 | F10: =Bal!C10 -> 0 | G10: =Bal!D10 -> 0 | H10: =Bal!E10 -> 0 | I10: =Bal!F10 -> 0 | J10: =Bal!G10 -> 0 | K10: =Bal!H10 -> 0 | L10: =Bal!I10 -> 0 | ... N10: =Bal!K10 -> 0
D11: =HLOOKUP(E11,$S$3:$EN$4,2,0) -> 1 | E11: =Bal!B11 -> Caja y Bancos | F11: =Bal!C11 -> 0 | G11: =Bal!D11 -> 0 | H11: =Bal!E11 -> 61506 | I11: =Bal!F11 -> 0 | J11: =Bal!G11 -> 0.02 | K11: =Bal!H11 -> 271489 | L11: =Bal!I11 -> 0.05 | ... N11: =Bal!K11 -> 0.03
D12: =HLOOKUP(E12,$S$3:$EN$4,2,0) -> 2 | E12: =Bal!B12 -> Cuentas por Cobrar | F12: =Bal!C12 -> 0 | G12: =Bal!D12 -> 0 | H12: =Bal!E12 -> 805016 | I12: =Bal!F12 -> 0 | J12: =Bal!G12 -> 0.21 | K12: =Bal!H12 -> 696737 | L12: =Bal!I12 -> 0.13 | ... N12: =Bal!K12 -> 0.11
D13: =HLOOKUP(E13,$S$3:$EN$4,2,0) -> 4 | E13: =Bal!B13 -> Deudores Diversos | F13: =Bal!C13 -> 0 | G13: =Bal!D13 -> 0 | H13: =Bal!E13 -> 696040 | I13: =Bal!F13 -> 0 | J13: =Bal!G13 -> 0.18 | K13: =Bal!H13 -> 2303156 | L13: =Bal!I13 -> 0.41 | ... N13: =Bal!K13 -> 0.45
D14: =HLOOKUP(E14,$S$3:$EN$4,2,0) -> 5 | E14: =Bal!B14 -> Inventarios | F14: =Bal!C14 -> 0 | G14: =Bal!D14 -> 0 | H14: =Bal!E14 -> 121292 | I14: =Bal!F14 -> 0 | J14: =Bal!G14 -> 0.03 | K14: =Bal!H14 -> 199339 | L14: =Bal!I14 -> 0.04 | ... N14: =Bal!K14 -> 0.05
B15: Caja y Bancos | C15: 1 | D15: =HLOOKUP(E15,$S$3:$EN$4,2,0) -> #N/A | E15: =Bal!B15 -> 0 | F15: =Bal!C15 -> 0 | G15: =Bal!D15 -> 0 | H15: =Bal!E15 -> 1683854 | I15: =Bal!F15 -> 0 | J15: =Bal!G15 -> 0.44 | K15: =Bal!H15 -> 3470721 | L15: =Bal!I15 -> 0.63 | ... N15: =Bal!K15 -> 0.64
B16: Cuentas por Cobrar | C16: 2 | D16: =HLOOKUP(E16,$S$3:$EN$4,2,0) -> #N/A | E16: =Bal!B16 -> ACTIVO FIJO | F16: =Bal!C16 -> 0 | G16: =Bal!D16 -> 0 | H16: =Bal!E16 -> 0 | I16: =Bal!F16 -> 0 | J16: =Bal!G16 -> 0 | K16: =Bal!H16 -> 0 | L16: =Bal!I16 -> 0 | ... N16: =Bal!K16 -> 0
B17: IVA por Acreditar | C17: 3 | D17: =HLOOKUP(E17,$S$3:$EN$4,2,0) -> #N/A | E17: =Bal!B17 -> 0 | F17: =Bal!C17 -> 0 | G17: =Bal!D17 -> 0 | H17: =Bal!E17 -> 0 | I17: =Bal!F17 -> 0 | J17: =Bal!G17 -> 0 | K17: =Bal!H17 -> 0 | L17: =Bal!I17 -> 0 | ... N17: =Bal!K17 -> 0
B18: Deudores Diversos | C18: 4 | D18: =HLOOKUP(E18,$S$3:$EN$4,2,0) -> 9 | E18: =Bal!B18 -> Terrenos y Edificios | F18: =Bal!C18 -> 0 | G18: =Bal!D18 -> 0 | H18: =Bal!E18 -> 287684 | I18: =Bal!F18 -> 0 | J18: =Bal!G18 -> 0.07 | K18: =Bal!H18 -> 287684 | L18: =Bal!I18 -> 0.05 | ... N18: =Bal!K18 -> 0.05
B19: Inventarios | C19: 5 | D19: =HLOOKUP(E19,$S$3:$EN$4,2,0) -> 10 | E19: =Bal!B19 -> Maquinaria y Equipo | F19: =Bal!C19 -> 0 | G19: =Bal!D19 -> 0 | H19: =Bal!E19 -> 1960982 | I19: =Bal!F19 -> 0 | J19: =Bal!G19 -> 0.5 | K19: =Bal!H19 -> 2362142 | L19: =Bal!I19 -> 0.42 | ... N19: =Bal!K19 -> 0.44
B20: Reclamaciones por Garantia | C20: 6 | D20: =HLOOKUP(E20,$S$3:$EN$4,2,0) -> 11 | E20: =Bal!B20 -> Muebles y Enseres | F20: =Bal!C20 -> 0 | G20: =Bal!D20 -> 0 | H20: =Bal!E20 -> 287942 | I20: =Bal!F20 -> 0 | J20: =Bal!G20 -> 0.07 | K20: =Bal!H20 -> 398840 | L20: =Bal!I20 -> 0.07 | ... N20: =Bal!K20 -> 0.08
B21: Cuentas por Cobrar Filiales | C21: 7 | D21: =HLOOKUP(E21,$S$3:$EN$4,2,0) -> 12 | E21: =Bal!B21 -> Equipo de Transporte | F21: =Bal!C21 -> 0 | G21: =Bal!D21 -> 0 | H21: =Bal!E21 -> 44065 | I21: =Bal!F21 -> 0 | J21: =Bal!G21 -> 0.01 | K21: =Bal!H21 -> 47054 | L21: =Bal!I21 -> 0.01 | ... N21: =Bal!K21 -> 0.01
B22: Otros Activos Circulantes | C22: 8 | D22: =HLOOKUP(E22,$S$3:$EN$4,2,0) -> 13 | E22: =Bal!B22 -> Depreciacion Acumulada | F22: =Bal!C22 -> 0 | G22: =Bal!D22 -> 0 | H22: =Bal!E22 -> -1014568 | I22: =Bal!F22 -> 0 | J22: =Bal!G22 -> -0.26 | K22: =Bal!H22 -> -1181927 | L22: =Bal!I22 -> -0.21 | ... N22: =Bal!K22 -> -0.23
D23: =HLOOKUP(E23,$S$3:$EN$4,2,0) -> #N/A | E23: =Bal!B23 -> 0 | F23: =Bal!C23 -> 0 | G23: =Bal!D23 -> 0 | H23: =Bal!E23 -> 1566105 | I23: =Bal!F23 -> 0 | J23: =Bal!G23 -> 0.39 | K23: =Bal!H23 -> 1913793 | L23: =Bal!I23 -> 0.34 | ... N23: =Bal!K23 -> 0.35
D24: =HLOOKUP(E24,$S$3:$EN$4,2,0) -> #N/A | E24: =Bal!B24 -> ACTIVO DIFERIDO | F24: =Bal!C24 -> 0 | G24: =Bal!D24 -> 0 | H24: =Bal!E24 -> 0 | I24: =Bal!F24 -> 0 | J24: =Bal!G24 -> 0 | K24: =Bal!H24 -> 0 | L24: =Bal!I24 -> 0 | ... N24: =Bal!K24 -> 0
D25: =HLOOKUP(E25,$S$3:$EN$4,2,0) -> #N/A | E25: =Bal!B25 -> 0 | F25: =Bal!C25 -> 0 | G25: =Bal!D25 -> 0 | H25: =Bal!E25 -> 0 | I25: =Bal!F25 -> 0 | J25: =Bal!G25 -> 0 | K25: =Bal!H25 -> 0 | L25: =Bal!I25 -> 0 | ... N25: =Bal!K25 -> 0
D26: =HLOOKUP(E26,$S$3:$EN$4,2,0) -> 16 | E26: =Bal!B26 -> Pagos Anticipados | F26: =Bal!C26 -> 0 | G26: =Bal!D26 -> 0 | H26: =Bal!E26 -> 20318 | I26: =Bal!F26 -> 0 | J26: =Bal!G26 -> 0.01 | K26: =Bal!H26 -> 41904 | L26: =Bal!I26 -> 0.01 | ... N26: =Bal!K26 -> 0
D27: =HLOOKUP(E27,$S$3:$EN$4,2,0) -> 17 | E27: =Bal!B27 -> Cargos Diferidos | F27: =Bal!C27 -> 0 | G27: =Bal!D27 -> 0 | H27: =Bal!E27 -> 630957 | I27: =Bal!F27 -> 0 | J27: =Bal!G27 -> 0.16 | K27: =Bal!H27 -> 144259 | L27: =Bal!I27 -> 0.03 | ... N27: =Bal!K27 -> 0.01
B28: Terrenos y Edificios | C28: 9 | D28: =HLOOKUP(E28,$S$3:$EN$4,2,0) -> 18 | E28: =Bal!B28 -> Inversiones en Valores | F28: =Bal!C28 -> 0 | G28: =Bal!D28 -> 0 | H28: =Bal!E28 -> 500 | I28: =Bal!F28 -> 0 | J28: =Bal!G28 -> 0 | K28: =Bal!H28 -> 500 | L28: =Bal!I28 -> 0 | ... N28: =Bal!K28 -> 0
B29: Maquinaria y Equipo | C29: 10 | D29: =HLOOKUP(E29,$S$3:$EN$4,2,0) -> #N/A | E29: =Bal!B29 -> 0 | F29: =Bal!C29 -> 0 | G29: =Bal!D29 -> 0 | H29: =Bal!E29 -> 651775 | I29: =Bal!F29 -> 0 | J29: =Bal!G29 -> 0.17 | K29: =Bal!H29 -> 186663 | L29: =Bal!I29 -> 0.04 | ... N29: =Bal!K29 -> 0.01
B30: Muebles y Enseres | C30: 11 | D30: =HLOOKUP(E30,$S$3:$EN$4,2,0) -> #N/A | E30: =Bal!B30 -> TOTAL DE ACTIVO | F30: =Bal!C30 -> 0 | G30: =Bal!D30 -> 0 | H30: =Bal!E30 -> 3901734 | I30: =Bal!F30 -> 0 | J30: =Bal!G30 -> 1 | K30: =Bal!H30 -> 5571177 | L30: =Bal!I30 -> 1 | ... N30: =Bal!K30 -> 1
B31: Equipo de Transporte | C31: 12 | D31: =HLOOKUP(E31,$S$3:$EN$4,2,0) -> #N/A | E31: =Bal!B31 -> PASIVO CIRCULANTE | F31: =Bal!C31 -> 0 | G31: =Bal!D31 -> 0 | H31: =Bal!E31 -> 0 | I31: =Bal!F31 -> 0 | J31: =Bal!G31 -> 0 | K31: =Bal!H31 -> 0 | L31: =Bal!I31 -> 0 | ... N31: =Bal!K31 -> 0
B32: Depreciacion Acumulada | C32: 13 | D32: =HLOOKUP(E32,$S$3:$EN$4,2,0) -> #N/A | E32: =Bal!B32 -> 0 | F32: =Bal!C32 -> 0 | G32: =Bal!D32 -> 0 | H32: =Bal!E32 -> 0 | I32: =Bal!F32 -> 0 | J32: =Bal!G32 -> 0 | K32: =Bal!H32 -> 0 | L32: =Bal!I32 -> 0 | ... N32: =Bal!K32 -> 0
B33: Revaluacion de Activos | C33: 14 | D33: =HLOOKUP(E33,$S$3:$EN$4,2,0) -> 20 | E33: =Bal!B33 -> Proveedores | F33: =Bal!C33 -> 0 | G33: =Bal!D33 -> 0 | H33: =Bal!E33 -> 44762 | I33: =Bal!F33 -> 0 | J33: =Bal!G33 -> 0.01 | K33: =Bal!H33 -> 30461 | L33: =Bal!I33 -> 0.01 | ... N33: =Bal!K33 -> 0
B34: Mejoras al Local Arrendado | C34: 15 | D34: =HLOOKUP(E34,$S$3:$EN$4,2,0) -> 21 | E34: =Bal!B34 -> Creditos a Corto Plazo | F34: =Bal!C34 -> 0 | G34: =Bal!D34 -> 0 | H34: =Bal!E34 -> 1035327 | I34: =Bal!F34 -> 0 | J34: =Bal!G34 -> 0.27 | K34: =Bal!H34 -> 1588080 | L34: =Bal!I34 -> 0.29 | ... N34: =Bal!K34 -> 0.18
D35: =HLOOKUP(E35,$S$3:$EN$4,2,0) -> 23 | E35: =Bal!B35 -> Impuestos a Pagar | F35: =Bal!C35 -> 0 | G35: =Bal!D35 -> 0 | H35: =Bal!E35 -> 85415 | I35: =Bal!F35 -> 0 | J35: =Bal!G35 -> 0.02 | K35: =Bal!H35 -> 116008 | L35: =Bal!I35 -> 0.02 | ... N35: =Bal!K35 -> 0.01
D36: =HLOOKUP(E36,$S$3:$EN$4,2,0) -> 24 | E36: =Bal!B36 -> Acreedores Diversos | F36: =Bal!C36 -> 0 | G36: =Bal!D36 -> 0 | H36: =Bal!E36 -> 34072 | I36: =Bal!F36 -> 0 | J36: =Bal!G36 -> 0.01 | K36: =Bal!H36 -> 720635 | L36: =Bal!I36 -> 0.13 | ... N36: =Bal!K36 -> 0.17
D37: =HLOOKUP(E37,$S$3:$EN$4,2,0) -> #N/A | E37: =Bal!B37 -> 0 | F37: =Bal!C37 -> 0 | G37: =Bal!D37 -> 0 | H37: =Bal!E37 -> 1199576 | I37: =Bal!F37 -> 0 | J37: =Bal!G37 -> 0.31 | K37: =Bal!H37 -> 2455184 | L37: =Bal!I37 -> 0.45 | ... N37: =Bal!K37 -> 0.36
D38: =HLOOKUP(E38,$S$3:$EN$4,2,0) -> #N/A | E38: =Bal!B38 -> PASIVO A LARGO PLAZO | F38: =Bal!C38 -> 0 | G38: =Bal!D38 -> 0 | H38: =Bal!E38 -> 0 | I38: =Bal!F38 -> 0 | J38: =Bal!G38 -> 0 | K38: =Bal!H38 -> 0 | L38: =Bal!I38 -> 0 | ... N38: =Bal!K38 -> 0
D39: =HLOOKUP(E39,$S$3:$EN$4,2,0) -> #N/A | E39: =Bal!B39 -> 0 | F39: =Bal!C39 -> 0 | G39: =Bal!D39 -> 0 | H39: =Bal!E39 -> 0 | I39: =Bal!F39 -> 0 | J39: =Bal!G39 -> 0 | K39: =Bal!H39 -> 0 | L39: =Bal!I39 -> 0 | ... N39: =Bal!K39 -> 0
B40: Pagos Anticipados | C40: 16 | D40: =HLOOKUP(E40,$S$3:$EN$4,2,0) -> 29 | E40: =Bal!B40 -> Creditos a Largo Plazo | F40: =Bal!C40 -> 0 | G40: =Bal!D40 -> 0 | H40: =Bal!E40 -> 777045 | I40: =Bal!F40 -> 0 | J40: =Bal!G40 -> 0.2 | K40: =Bal!H40 -> 659414 | L40: =Bal!I40 -> 0.12 | ... N40: =Bal!K40 -> 0.12
B41: Cargos Diferidos | C41: 17 | D41: =HLOOKUP(E41,$S$3:$EN$4,2,0) -> #N/A | E41: =Bal!B41 -> 0 | F41: =Bal!C41 -> 0 | G41: =Bal!D41 -> 0 | H41: =Bal!E41 -> 777045 | I41: =Bal!F41 -> 0 | J41: =Bal!G41 -> 0.2 | K41: =Bal!H41 -> 659414 | L41: =Bal!I41 -> 0.12 | ... N41: =Bal!K41 -> 0.12
B42: Inversiones en Valores | C42: 18 | D42: =HLOOKUP(E42,$S$3:$EN$4,2,0) -> #N/A | E42: =Bal!B42 -> 0 | F42: =Bal!C42 -> 0 | G42: =Bal!D42 -> 0 | H42: =Bal!E42 -> 0 | I42: =Bal!F42 -> 0 | J42: =Bal!G42 -> 0 | K42: =Bal!H42 -> 0 | L42: =Bal!I42 -> 0 | ... N42: =Bal!K42 -> 0
B43: Credito al Salario | C43: 19 | D43: =HLOOKUP(E43,$S$3:$EN$4,2,0) -> #N/A | E43: =Bal!B43 -> 0 | F43: =Bal!C43 -> 0 | G43: =Bal!D43 -> 0 | H43: =Bal!E43 -> 0 | I43: =Bal!F43 -> 0 | J43: =Bal!G43 -> 0 | K43: =Bal!H43 -> 0 | L43: =Bal!I43 -> 0 | ... N43: =Bal!K43 -> 0
...

Sheet PROY CLIENTE
C5: =#REF! -> #REF!
C6: Proyección Cliente
E8: Real | F8: Estimado | G8: Proyección
E9: 2008 | F9: 2009 | G9: 2010 | H9: 2011 | I9: 2012
C11: Ingresos | E11: =#REF! -> #REF! | F11: 68184 | G11: 155186 | H11: 162946 | I11: 171093
C12: Costo de Venta | E12: =#REF!+#REF! -> #REF! | F12: 49774 | G12: 113286 | H12: 118950 | I12: 124897
C14: Utilidad Bruta | E14: =E11-E12 -> #REF! | F14: =F11-F12 -> 18410 | G14: =G11-G12 -> 41900 | H14: =H11-H12 -> 43996 | I14: =I11-I12 -> 46196
E15: =E14/E11 -> #REF! | F15: =F14/F11 -> 0.27000469 | G15: =G14/G11 -> 0.26999858 | H15: =H14/H11 -> 0.27000356 | I15: =I14/I11 -> 0.2700052
C17: Gastos de Admon y Vta | E17: =#REF! -> #REF! | F17: 15682 | G17: 35693 | H17: 37478 | I17: 39352
C19: Utilidad operativa | E19: =E14-E17 -> #REF! | F19: =F14-F17 -> 2728 | G19: =G14-G17 -> 6207 | H19: =H14-H17 -> 6518 | I19: =I14-I17 -> 6844
E20: =E19/E11 -> #REF! | F20: =F19/F11 -> 0.040009386 | G20: =G19/G11 -> 0.039997165 | H20: =H19/H11 -> 0.040000982 | I20: =I19/I11 -> 0.040001637
C22: Gastos Financieros | E22: =#REF! -> #REF! | F22: 651 | G22: 1617 | H22: 1107 | I22: 759
C24: Otros | E24: =#REF! -> #REF! | F24: 0 | G24: 0 | H24: 0 | I24: 0
C26: Impuestos | E26: =#REF! -> #REF! | F26: 312 | G26: 688 | H26: 812 | I26: 913
C28: Utilidad Neta | E28: =E19+E24-E22-E26 -> #REF! | F28: =F19+F24-F22-F26 -> 1765 | G28: =G19+G24-G22-G26 -> 3902 | H28: =H19+H24-H22-H26 -> 4599 | I28: =I19+I24-I22-I26 -> 5172
E29: =E28/E11 -> #REF! | F29: =F28/F11 -> 0.025885838 | G29: =G28/G11 -> 0.025144021 | H29: =H28/H11 -> 0.028224074 | I29: =I28/I11 -> 0.030229174
C33: Premisas de elaboración
C35: 1.- Ingresos para 2009 se consideran los mismos ingresos obtenidos para el primer semestre del año
C36: 2.- En 2010 se considera un aumento de un 13.8% derivado de nuestro ingreso a nivel nacional en cadena de autoservicios Costco y para los años subsecuentes se contemplo un incremento del 5%
C37: 3.- El costo se mantuvo en el mismo nivel (73% sobre ventas)
C38: 4.- Gastos de Distribución se mantuvieron en el mismo nivel (23% sobre ventas)
C39: 5.- Los Gastos Financieros fueron calculados de acuerdo a tablas de amortización individualmente por tipo de crédito.

Sheet PROYECCIONES
C5: =#REF! -> #REF!
C6: Proyección del Cliente
F8: Real | G8: Estimado | H8: Proyección
F9: 2008 | G9: 2009 | H9: 2010 | I9: 2011 | J9: 2012 | K9: 2013 | L9: 2014
C11: Ingresos | F11: =#REF! -> #REF! | G11: =138845+161898+10337 -> 311080 | H11: =138737+474028+11493 -> 624258 | I11: =141511+565143+11953 -> 718607 | J11: =144342+565143+12431 -> 721916 | K11: =147228+565143+12928 -> 725299 | L11: =150173+565143+13445 -> 728761
C12: Costo de Venta | F12: =#REF!+#REF! -> #REF! | G12: =91476+133009+8123 -> 232608 | H12: =91258+288879+9171 -> 389308 | I12: =93084+343687+9538 -> 446309 | J12: =94945+343687+9920 -> 448552 | K12: =96844+343687+10317 -> 450848 | L12: =98781+343687+10729 -> 453197
F13: =F12/F11 -> #REF! | G13: =G12/G11 -> 0.74774335 | H13: =H12/H11 -> 0.62363318 | I13: =I12/I11 -> 0.62107522 | J13: =J12/J11 -> 0.62133545 | K13: =K12/K11 -> 0.62160295 | L13: =L12/L11 -> 0.62187329
C15: Utilidad Bruta | F15: =F11-F12 -> #REF! | G15: =G11-G12 -> 78472 | H15: =H11-H12 -> 234950 | I15: =I11-I12 -> 272298 | J15: =J11-J12 -> 273364 | K15: =K11-K12 -> 274451 | L15: =L11-L12 -> 275564
F16: =F15/F11 -> #REF! | G16: =G15/G11 -> 0.25225665 | H16: =H15/H11 -> 0.37636682 | I16: =I15/I11 -> 0.37892478 | J16: =J15/J11 -> 0.37866455 | K16: =K15/K11 -> 0.37839705 | L16: =L15/L11 -> 0.37812671
C18: Gastos de Admon y Vta | F18: =#REF! -> #REF! | G18: =11636+8063+6801+3397 -> 29897 | H18: =12287+9543+3397 -> 25227 | I18: =12778+9925+3533 -> 26236 | J18: =13289+10322+3674 -> 27285 | K18: =13821+10735+3820 -> 28376 | L18: =14374+11165 -> 25539
C20: Utilidad operativa | F20: =F15-F18 -> #REF! | G20: =G15-G18 -> 48575 | H20: =H15-H18 -> 209723 | I20: =I15-I18 -> 246062 | J20: =J15-J18 -> 246079 | K20: =K15-K18 -> 246075 | L20: =L15-L18 -> 250025
F21: =F20/F11 -> #REF! | G21: =G20/G11 -> 0.15614954 | H21: =H20/H11 -> 0.33595565 | I21: =I20/I11 -> 0.34241526 | J21: =J20/J11 -> 0.3408693 | K21: =K20/K11 -> 0.33927387 | L21: =L20/L11 -> 0.3430823
C23: Gastos Financieros | F23: =#REF! -> #REF! | G23: 7209 | H23: 3257 | I23: 3387 | J23: 3522 | K23: 3663 | L23: 3810
C25: Otros | F25: =#REF! -> #REF! | G25: 1964 | H25: 2679 | I25: 2786 | J25: 0 | K25: 0 | L25: 0
C27: Impuestos | F27: =#REF! -> #REF! | G27: 0 | H27: 0 | I27: 0 | J27: 0 | K27: 0 | L27: 0
C29: Utilidad Neta | F29: =F20+F25-F23-F27 -> #REF! | G29: =G20+G25-G23-G27 -> 43330 | H29: =H20+H25-H23-H27 -> 209145 | I29: =I20+I25-I23-I27 -> 245461 | J29: =J20+J25-J23-J27 -> 242557 | K29: =K20+K25-K23-K27 -> 242412 | L29: =L20+L25-L23-L27 -> 246215
F30: =F29/F11 -> #REF! | G30: =G29/G11 -> 0.13928893 | H30: =H29/H11 -> 0.33502975 | I30: =I29/I11 -> 0.34157892 | J30: =J29/J11 -> 0.33599061 | K30: =K29/K11 -> 0.33422354 | L30: =L29/L11 -> 0.33785425
C32: Cuentas por Cobrar | D32: =#REF! -> #REF! | E32: =#REF! -> #REF! | F32: =F11/360*$E$32 -> #REF! | G32: =G11/360*$E$32 -> #REF! | H32: =H11/360*$E$32 -> #REF! | I32: =I11/360*$E$32 -> #REF! | J32: =J11/360*$E$32 -> #REF! | K32: =K11/360*$E$32 -> #REF! | L32: =L11/360*$E$32 -> #REF!
C33: Inventario | D33: =#REF! -> #REF! | E33: =#REF! -> #REF! | F33: =F12/360*$E$33 -> #REF! | G33: =G12/360*$E$33 -> #REF! | H33: =H12/360*$E$33 -> #REF! | I33: =I12/360*$E$33 -> #REF! | J33: =J12/360*$E$33 -> #REF! | K33: =K12/360*$E$33 -> #REF! | L33: =L12/360*$E$33 -> #REF!
C34: Proveedores | D34: =#REF! -> #REF! | E34: =#REF! -> #REF! | F34: =F12/360*$E$34 -> #REF! | G34: =G12/360*$E$34 -> #REF! | H34: =H12/360*$E$34 -> #REF! | I34: =I12/360*$E$34 -> #REF! | J34: =J12/360*$E$34 -> #REF! | K34: =K12/360*$E$34 -> #REF! | L34: =L12/360*$E$34 -> #REF!
C36: Gastos Financieros | H36: 2010 | I36: 2011 | J36: 2012 | K36: 2013 | L36: 2014
C37: HSBC | D37: 120 | H37: 0 | I37: 0 | J37: 0 | K37: 0 | L37: 0
C38: Frost Bank (ACCC) | D38: 12800 | H38: =1280-190 -> 1090 | I38: 1280 | J38: 1280 | K38: 1280 | L38: 1280
C39: SAT | D39: 4864 | H39: 486.4 | I39: 243.2
C40: Banregio ACCC | D40: 7000 | H40: 700 | I40: 700 | J40: 700
C41: Banregio ACS | D41: 8000 | H41: 726.66667 | I41: 566.66667 | J41: 406.66667 | K41: 246.66667 | L41: 86.666667
C42: Banregio AF | D42: 3000 | H42: 254.16667 | I42: 154.16667 | J42: 54.166667
C43: Otros | I43: 443 | J43: 1081 | K43: 2136 | L43: 2443
C47: Total | D47: =SUM(D37:D46) -> 35784 | H47: =SUM(H37:H46) -> 3257.2333 | I47: =SUM(I37:I46) -> 3387.0333 | J47: =SUM(J37:J46) -> 3521.8333 | K47: =SUM(K37:K46) -> 3662.6667 | L47: =SUM(L37:L46) -> 3809.6667
C49: Pago a Capital
C50: =C37 -> HSBC | D50: =D37 -> 120 | H50: 120
C51: =C38 -> Frost Bank (ACCC) | D51: =D38 -> 12800 | H51: 0
C52: =C39 -> SAT | D52: =D39 -> 4864 | H52: 4864 | I52: 0
C53: =C40 -> Banregio ACCC | D53: =D40 -> 7000 | H53: 0 | I53: 0 | J53: 0
C54: =C41 -> Banregio ACS | D54: =D41 -> 8000 | H54: 1600 | I54: 1600 | J54: 1600 | K54: 1600 | L54: 1600
C55: =C42 -> Banregio AF | D55: =D42 -> 3000 | H55: 1000 | I55: 1000 | J55: 1000
C56: otros ACCC
C60: Total | D60: =SUM(D50:D59) -> 35784 | H60: =SUM(H50:H59) -> 7584 | I60: =SUM(I50:I59) -> 2600 | J60: =SUM(J50:J59) -> 2600 | K60: =SUM(K50:K59) -> 1600 | L60: =SUM(L50:L59) -> 1600
C63: Premisas de elaboración
C65: 1.- Se consideran los ingresos proyectados por el cliente
...

Sheet Flujo
C3: =#REF! -> #REF!
C4: Flujo de Efectivo Proyectado del Cliente
F5: =+PROYECCIONES!H9 -> 2010 | G5: =+PROYECCIONES!I9 -> 2011 | H5: =+PROYECCIONES!J9 -> 2012 | I5: =+PROYECCIONES!K9 -> 2013 | J5: =+PROYECCIONES!L9 -> 2014
C7: UAFIR | F7: =PROYECCIONES!H20 -> 209723 | G7: =PROYECCIONES!I20 -> 246062 | H7: =PROYECCIONES!J20 -> 246079 | I7: =PROYECCIONES!K20 -> 246075 | J7: =PROYECCIONES!L20 -> 250025
D9: DEPRECIACIÓN DEL EJERCICIO | F9: 0 | G9: 0 | H9: 0 | I9: 0 | J9: 0
C11: UAFIRDA | F11: =+F7+F9 -> 209723 | G11: =+G7+G9 -> 246062 | H11: =+H7+H9 -> 246079 | I11: =+I7+I9 -> 246075 | J11: =+J7+J9 -> 250025
D13: CUENTAS POR COBRAR | F13: =PROYECCIONES!G32-PROYECCIONES!H32 -> #REF! | G13: =PROYECCIONES!H32-PROYECCIONES!I32 -> #REF! | H13: =PROYECCIONES!I32-PROYECCIONES!J32 -> #REF! | I13: =PROYECCIONES!J32-PROYECCIONES!K32 -> #REF! | J13: =PROYECCIONES!K32-PROYECCIONES!L32 -> #REF!
D14: INVENTARIOS | F14: =PROYECCIONES!G33-PROYECCIONES!H33 -> #REF! | G14: =PROYECCIONES!H33-PROYECCIONES!I33 -> #REF! | H14: =PROYECCIONES!I33-PROYECCIONES!J33 -> #REF! | I14: =PROYECCIONES!J33-PROYECCIONES!K33 -> #REF! | J14: =PROYECCIONES!K33-PROYECCIONES!L33 -> #REF!
D15: PROVEEDORES | F15: =PROYECCIONES!H34-PROYECCIONES!G34 -> #REF! | G15: =PROYECCIONES!I34-PROYECCIONES!H34 -> #REF! | H15: =PROYECCIONES!J34-PROYECCIONES!I34 -> #REF! | I15: =PROYECCIONES!K34-PROYECCIONES!J34 -> #REF! | J15: =PROYECCIONES!L34-PROYECCIONES!K34 -> #REF!
E16: SUBTOTAL OPERACIÓN | F16: =SUM(F13:F15) -> #REF! | G16: =SUM(G13:G15) -> #REF! | H16: =SUM(H13:H15) -> #REF! | I16: =SUM(I13:I15) -> #REF! | J16: =SUM(J13:J15) -> #REF!
C18: FLUJO DE OPERACIÓN | F18: =+F11+F16 -> #REF! | G18: =+G11+G16 -> #REF! | H18: =+H11+H16 -> #REF! | I18: =+I11+I16 -> #REF! | J18: =+J11+J16 -> #REF!
D20: GASTOS FINANCIEROS | F20: =PROYECCIONES!H23 -> 3257 | G20: =PROYECCIONES!I23 -> 3387 | H20: =PROYECCIONES!J23 -> 3522 | I20: =PROYECCIONES!K23 -> 3663 | J20: =PROYECCIONES!L23 -> 3810
C22: FLUJO ANTES DE IMPUESTOS | F22: =F18-F20 -> #REF! | G22: =G18-G20 -> #REF! | H22: =H18-H20 -> #REF! | I22: =I18-I20 -> #REF! | J22: =J18-J20 -> #REF!
D24: IMPUESTOS PAGADOS | F24: =PROYECCIONES!G27 -> 0 | G24: =PROYECCIONES!H27 -> 0 | H24: =PROYECCIONES!I27 -> 0 | I24: =PROYECCIONES!J27 -> 0 | J24: =PROYECCIONES!K27 -> 0
C26: FLUJO NETO | F26: =F22-F24 -> #REF! | G26: =G22-G24 -> #REF! | H26: =H22-H24 -> #REF! | I26: =I22-I24 -> #REF! | J26: =J22-J24 -> #REF!
C28: OTRAS ACTIVIDADES
D29: DEUDORES DIVERSOS | F29: 0 | G29: 0 | H29: 0 | I29: 0 | J29: 0
D30: OTROS ACTIVOS | F30: 0 | G30: 0 | H30: 0 | I30: 0 | J30: 0
E31: SUBTOTAL OTROS | F31: =SUM(F29:F30) -> 0 | G31: =SUM(G29:G30) -> 0 | H31: =SUM(H29:H30) -> 0 | I31: =SUM(I29:I30) -> 0 | J31: =SUM(J29:J30) -> 0
C33: ACTIVIDADES DE INVERSIÓN
D34: ADQUISICIÓN O VENTA DE ACTIVO FIJO | F34: 0 | G34: 0 | H34: 0 | I34: 0 | J34: 0
E35: SUBTOTAL INVERSIONES | F35: =F34 -> 0 | G35: =G34 -> 0 | H35: =H34 -> 0 | I35: =I34 -> 0 | J35: =J34 -> 0
C37: FLUJO DESPUÉS DE INVERSIONES | F37: =+F26+F35+F31 -> #REF! | G37: =+G26+G35+G31 -> #REF! | H37: =+H26+H35+H31 -> #REF! | I37: =+I26+I35+I31 -> #REF! | J37: =+J26+J35+J31 -> #REF!
C39: FUENTES DE FINANCIAMIENTO
D40: PASIVOS FINANCIEROS | F40: =PROYECCIONES!H60*-1 -> -7584 | G40: =PROYECCIONES!I60*-1 -> -2600 | H40: =PROYECCIONES!J60*-1 -> -2600 | I40: =PROYECCIONES!K60*-1 -> -1600 | J40: =PROYECCIONES!L60*-1 -> -1600
D41: ACREEDORES DIVERSOS | F41: 0 | G41: 0 | H41: 0 | I41: 0 | J41: 0
D42: DIF EN UTILIDADES RET / DECRETO DE DIVIDENDOS | F42: 0 | G42: 0 | H42: 0 | I42: 0 | J42: 0
D43: CAPITAL SOCIAL | F43: 0 | G43: 0 | H43: 0 | I43: 0 | J43: 0
D44: RESERVAS | F44: 0 | G44: 0 | H44: 0 | I44: 0 | J44: 0
D45: APORTACIONES P FUTUROS AUMEN. | F45: 0 | G45: 0 | H45: 0 | I45: 0 | J45: 0
E46: SUBTOTAL FUENTES | F46: =SUM(F40:F45) -> -7584 | G46: =SUM(G40:G45) -> -2600 | H46: =SUM(H40:H45) -> -2600 | I46: =SUM(I40:I45) -> -1600 | J46: =SUM(J40:J45) -> -1600
C48: FLUJO DESPUÉS DE FINANCIAMIENTO | F48: =+F37+F46 -> #REF! | G48: =+G37+G46 -> #REF! | H48: =+H37+H46 -> #REF! | I48: =+I37+I46 -> #REF! | J48: =+J37+J46 -> #REF!
C50: VARIACIÓN EN CAJA | F50: 0 | G50: 0 | H50: 0 | I50: 0 | J50: 0
C52: Cobertura de deuda | F52: =F26/(F40*-1) -> #REF! | G52: =G26/(G40*-1) -> #REF! | H52: =H26/(H40*-1) -> #REF! | I52: =I26/(I40*-1) -> #REF! | J52: =J26/(J40*-1) -> #REF!
C54: Cobertura de Intereses | F54: =F18/F20 -> #REF! | G54: =G18/G20 -> #REF! | H54: =H18/H20 -> #REF! | I54: =I18/I20 -> #REF! | J54: =J18/J20 -> #REF!

Sheet Proy banco
C5: =#REF! -> #REF!
C6: Proyección (Sensibilizado)
F8: Real | G8: Estimado | H8: Proyección
F9: 2008 | G9: 2009 | H9: 2010 | I9: 2011 | J9: 2012 | K9: 2013 | L9: 2014
C11: Ingresos | F11: =#REF! -> #REF! | G11: =138845+161898+10337 -> 311080 | H11: =138737+474028+11493 -> 624258 | I11: =141511+565143+11953 -> 718607 | J11: =144342+565143+12431 -> 721916 | K11: =147228+565143+12928 -> 725299 | L11: =150173+565143+13445 -> 728761
C12: Costo de Venta | F12: =#REF!+#REF! -> #REF! | G12: =+G13*G11 -> 242642.4 | H12: =+H13*H11 -> 518134.14 | I12: =+I13*I11 -> 596443.81 | J12: =+J13*J11 -> 599190.28 | K12: =+K13*K11 -> 601998.17 | L12: =+L13*L11 -> 604871.63
F13: =F12/F11 -> #REF! | G13: 0.78 | H13: 0.83 | I13: 0.83 | J13: 0.83 | K13: 0.83 | L13: 0.83
C15: Utilidad Bruta | F15: =F11-F12 -> #REF! | G15: =G11-G12 -> 68437.6 | H15: =H11-H12 -> 106123.86 | I15: =I11-I12 -> 122163.19 | J15: =J11-J12 -> 122725.72 | K15: =K11-K12 -> 123300.83 | L15: =L11-L12 -> 123889.37
F16: =F15/F11 -> #REF! | G16: =G15/G11 -> 0.22 | H16: =H15/H11 -> 0.17 | I16: =I15/I11 -> 0.17 | J16: =J15/J11 -> 0.17 | K16: =K15/K11 -> 0.17 | L16: =L15/L11 -> 0.17
C18: Gastos de Admon y Vta | F18: =#REF! -> #REF! | G18: =11636+8063+6801+3397 -> 29897 | H18: =12287+9543+3397 -> 25227 | I18: =12778+9925+3533 -> 26236 | J18: =13289+10322+3674 -> 27285 | K18: =13821+10735+3820 -> 28376 | L18: =14374+11165 -> 25539
F19: =+F18/F11 -> #REF! | G19: =+G18/G11 -> 0.096107111 | H19: =+H18/H11 -> 0.040411176 | I19: =+I18/I11 -> 0.036509525 | J19: =+J18/J11 -> 0.037795256 | K19: =+K18/K11 -> 0.039123175 | L19: =+L18/L11 -> 0.035044411
C20: Utilidad operativa | F20: =F15-F18 -> #REF! | G20: =G15-G18 -> 38540.6 | H20: =H15-H18 -> 80896.86 | I20: =I15-I18 -> 95927.19 | J20: =J15-J18 -> 95440.72 | K20: =K15-K18 -> 94924.83 | L20: =L15-L18 -> 98350.37
F21: =F20/F11 -> #REF! | G21: =G20/G11 -> 0.12389289 | H21: =H20/H11 -> 0.12958882 | I21: =I20/I11 -> 0.13349048 | J21: =J20/J11 -> 0.13220474 | K21: =K20/K11 -> 0.13087682 | L21: =L20/L11 -> 0.13495559
C23: Gastos Financieros | F23: =#REF! -> #REF! | G23: 7209 | H23: 3257 | I23: 3387 | J23: 3522 | K23: 3663 | L23: 3810
C25: Otros | F25: =#REF! -> #REF! | G25: 1964 | H25: 0 | I25: 0 | J25: 0 | K25: 0 | L25: 0
C27: Impuestos | F27: =#REF! -> #REF! | G27: 0 | H27: =H11*0.1 -> 62425.8 | I27: =I11*0.1 -> 71860.7 | J27: =J11*0.1 -> 72191.6 | K27: =K11*0.1 -> 72529.9 | L27: =L11*0.1 -> 72876.1
C29: Utilidad Neta | F29: =F20+F25-F23-F27 -> #REF! | G29: =G20+G25-G23-G27 -> 33295.6 | H29: =H20+H25-H23-H27 -> 15214.06 | I29: =I20+I25-I23-I27 -> 20679.49 | J29: =J20+J25-J23-J27 -> 19727.12 | K29: =K20+K25-K23-K27 -> 18731.93 | L29: =L20+L25-L23-L27 -> 21664.27
